Workbook
Name 目标3: OFFSET('5绘图数据'!$F$3,0,0,'[1]0信息维护'!$M$6)
Name 总目标: OFFSET('5绘图数据'!$H$3,0,0,'[1]0信息维护'!$M$6)

Sheet 0信息维护
A1: 操作说明（红色字体为说明，所有表格黑色字体不要更改；只可更改蓝色字体部分的文字和数据；不能随意删除表格中的行、列或者调整表格的列宽）； 0信息维护：此表需要维护显示蓝色字体部分的数据，无则输入0或者不填数据； 1课程考核方式及成绩组成:此表蓝色字体部分输入学生基本信息和各考核方式、各目标的分值（每种考核方式的满分为100分），若无则输入0或者不填数据； 2间接评价:此表蓝色字体部分输入各目标选择A、B、C、D、E的问卷统计结果； 3课程达成度分析报告:此表数据、图片都是自动生成，只需填写蓝色字体部分的课程分析和改进措施； 4学生课程目标达成度、5绘图数据:此表数据是自动生成，只需根据班级实际学生数在表格末尾处删除多余行数或增加相应行数（增加行时，光标放在表格右下角变成“十”时直接拖拉到最后一名学生所在的行）。
A2: 一、课程基本信息
A3: 课程名称 | D3: 数据结构与算法 | J3: 课程编码 | M3: N19ZY11005
A4: 课程类别 | D4: 专业核心必修课程 | J4: 学时/学分 | M4: 96/5
A5: 开课学期 | D5: 2023-2024-2 | J5: 授课对象 | M5: 计算机学院2022级5、6班
A6: 选课人数 | D6: 141 | J6: 参评人数 | M6: 141
A7: 任课教师 | D7: 任春华、段少松 | J7: 课程责任人 | M7: 任春华老师
A8: 开课学部（院） | D8: 人工智能与大数据学部 | J8: 专业 | M8: 软件工程
A10: 二、课程目标与毕业要求的对应关系
A11: 毕业要求 课程目标 | E11: 支撑的毕业要求指标点 | P11: 支撑强度
A12: 课程总目标 | B12: 课程目标1 | E12: 学生具备分析线性表、栈和队列、串、数组和广义表、树和二叉树、图等各种基本数据结构的能力；能够针对具体问题，通过定义抽象数学模型、算法并求解。 | P12: L
B13: 课程目标2 | E13: 针对工程应用问题，学生能够利用抽象数据结构思维的能力，比较和综合各种方案在逻辑结构、存储结构的优劣。 | P13: H
B14: 课程目标3 | E14: 学生能够运用数据结构与算法的基本原理，识别和判断复杂软件工程问题中数据结构使用和算法选择的关键环节。 | P14: M
B15: 课程目标4 | E15: 学生结合具体应用案例，能够认识到有多种逻辑结构和存储结构可供选择，通过网络、文献、大模型等方法寻求应用案例的解决方案。 | P15: H
B16: 课程目标5
B17: 课程目标6
B18: 课程目标7
A20: 注：此表中所有信息应与相应课程教学大纲保持一致，H、M、L分别代表高、中、低支撑。
A22: 三、课程目标评价方式
A23: (1) 过程性评价构成及比例
A24: 过程性评价构成及比例 | E24: 平时作业 | I24: 实验考核 | R24: 合计 | S24: 归一化
A25: 课程目标1 | E25: 0.4 | I25: 0 | R25: =SUM(E25:Q25) -> 0.4 | S25: =IF($R25=0,0,E25/$R25) -> 1 | T25: =IF($R25=0,0,I25/$R25) -> 0 | U25: =IF($R25=0,0,L25/$R25) -> 0 | V25: =IF($R25=0,0,O25/$R25) -> 0
A26: 课程目标2 | E26: 0.6 | I26: 0 | R26: =SUM(E26:Q26) -> 0.6 | S26: =IF($R26=0,0,E26/$R26) -> 1 | T26: =IF($R26=0,0,I26/$R26) -> 0 | U26: =IF($R26=0,0,L26/$R26) -> 0 | V26: =IF($R26=0,0,O26/$R26) -> 0
A27: 课程目标3 | E27: 0 | I27: 0 | R27: =SUM(E27:Q27) -> 0 | S27: =IF($R27=0,0,E27/$R27) -> 0 | T27: =IF($R27=0,0,I27/$R27) -> 0 | U27: =IF($R27=0,0,L27/$R27) -> 0 | V27: =IF($R27=0,0,O27/$R27) -> 0
A28: 课程目标4 | E28: 0 | I28: 1 | R28: =SUM(E28:Q28) -> 1 | S28: =IF($R28=0,0,E28/$R28) -> 0 | T28: =IF($R28=0,0,I28/$R28) -> 1 | U28: =IF($R28=0,0,L28/$R28) -> 0 | V28: =IF($R28=0,0,O28/$R28) -> 0
A29: 课程目标5 | I29: 0 | R29: =SUM(E29:Q29) -> 0 | S29: =IF($R29=0,0,E29/$R29) -> 0 | T29: =IF($R29=0,0,I29/$R29) -> 0 | U29: =IF($R29=0,0,L29/$R29) -> 0 | V29: =IF($R29=0,0,O29/$R29) -> 0
A30: 课程目标6 | E30: 0 | I30: 0 | R30: =SUM(E30:Q30) -> 0 | S30: =IF($R30=0,0,E30/$R30) -> 0 | T30: =IF($R30=0,0,I30/$R30) -> 0 | U30: =IF($R30=0,0,L30/$R30) -> 0 | V30: =IF($R30=0,0,O30/$R30) -> 0
A31: 课程目标7 | E31: 0 | I31: 0 | R31: =SUM(E31:Q31) -> 0 | S31: =IF($R31=0,0,E31/$R31) -> 0 | T31: =IF($R31=0,0,I31/$R31) -> 0 | U31: =IF($R31=0,0,L31/$R31) -> 0 | V31: =IF($R31=0,0,O31/$R31) -> 0
A32: 备注 | E32: 每列和为100%，单元格表示某一种考核方式的给课程目标的赋分 | R32: 此处不用设置，主要用于评测考核方式对目标的支撑度
A33: (2) 直接评价构成及比例
A34: 直接评价构成及比例 | E34: 过程性评价 | I34: 结果性评价 | M34: 备注
A35: 课程目标1 | E35: 0.5 | I35: 0.5 | M35: 横行等于100%
A36: 课程目标2 | E36: 0.5 | I36: 0.5
A37: 课程目标3 | E37: 0 | I37: 1
A38: 课程目标4 | E38: 1 | I38: 0
A39: 课程目标5 | E39: 0 | I39: 0
A40: 课程目标6 | E40: 0 | I40: 0
A41: 课程目标7 | E41: 0 | I41: 0
A43: (3) 间接评价构成及比例
A44: 间接评价构成及比例 | E44: 学生调查问卷 | I44: 其它 | N44: 备注
...

Sheet 1课程考核方式及成绩组成
A1: 课程考核方式及成绩组成
A2: 课程： | C2: ='0信息维护'!D3 -> 数据结构与算法 | G2: 课程编码： | O2: ='0信息维护'!M3 -> N19ZY11005 | AD2: 专业： | AF2: ='0信息维护'!M8 -> 软件工程
A3: 班级： | C3: ='0信息维护'!M5 -> 计算机学院2022级5、6班 | G3: 开课学部（院）： | O3: ='0信息维护'!D8 -> 人工智能与大数据学部 | AD3: 任课教师： | AF3: ='0信息维护'!D7 -> 任春华、段少松
A6: 序号 | B6: 学生基本信息 | F6: ='0信息维护'!E24 -> 平时作业 | N6: ='0信息维护'!I24 -> 实验考核 | V6: ='0信息维护'!L24 -> 0 | AD6: ='0信息维护'!O24 -> 0 | AL6: ='0信息维护'!I34 -> 结果性评价
F7: （满分100分） | N7: （满分100分） | V7: （满分100分） | AD7: （满分100分） | AL7: （满分100分）
B8: 专业名 | C8: 班级 | D8: 学号 | E8: 姓名 | F8: 目标1 | G8: 目标2 | H8: 目标3 | I8: 目标4 | J8: 目标5 | K8: 目标6 | L8: 目标7 | M8: 总分 | N8: 目标1 | O8: 目标2 | P8: 目标3 | Q8: 目标4 | R8: 目标5 | S8: 目标6 | T8: 目标7 | U8: 总分 | V8: 目标1 | W8: 目标2 | X8: 目标3 | Y8: 目标4 | Z8: 目标5 | AA8: 目标6 | AB8: 目标7 | AC8: 总分 | AD8: 目标1 | AE8: 目标2 | AF8: 目标3 | AG8: 目标4 | AH8: 目标5 | AI8: 目标6 | AJ8: 目标7 | AK8: 总分 | AL8: 目标1 | AM8: 目标2 | AN8: 目标3 | AO8: 目标4 | AP8: 目标5 | AQ8: 目标6 | AR8: 目标7 | AS8: 总分
B9: 目标分值 | F9: ='0信息维护'!I85 -> 40 | G9: ='0信息维护'!I91 -> 60 | H9: ='0信息维护'!I97 -> 0 | I9: ='0信息维护'!I103 -> 0 | J9: ='0信息维护'!I109 -> 0 | K9: ='0信息维护'!I115 -> 0 | L9: ='0信息维护'!I121 -> 0 | M9: =SUM(F9:L9) -> 100 | N9: ='0信息维护'!I86 -> 0 | O9: ='0信息维护'!I92 -> 0 | P9: ='0信息维护'!I98 -> 0 | Q9: ='0信息维护'!I104 -> 100 | R9: ='0信息维护'!I110 -> 0 | S9: ='0信息维护'!I116 -> 0 | T9: ='0信息维护'!I122 -> 0 | U9: =SUM(N9:T9) -> 100 | V9: ='0信息维护'!I87 -> 0 | W9: ='0信息维护'!I93 -> 0 | X9: ='0信息维护'!I99 -> 0 | Y9: ='0信息维护'!I105 -> 0 | Z9: ='0信息维护'!I111 -> 0 | AA9: ='0信息维护'!I117 -> 0 | AB9: ='0信息维护'!I123 -> 0 | AC9: =SUM(V9:AB9) -> 0 | AD9: ='0信息维护'!I88 -> 0 | AE9: ='0信息维护'!I94 -> 0 | AF9: ='0信息维护'!I100 -> 0 | AG9: ='0信息维护'!I106 -> 0 | AH9: ='0信息维护'!I112 -> 0 | AI9: ='0信息维护'!I118 -> 0 | AJ9: ='0信息维护'!I124 -> 0 | AK9: =SUM(AD9:AJ9) -> 0 | AL9: ='0信息维护'!I89 -> 36 | AM9: ='0信息维护'!I95 -> 30 | AN9: ='0信息维护'!I101 -> 34 | AO9: ='0信息维护'!I107 -> 0 | AP9: ='0信息维护'!I113 -> 0 | AQ9: ='0信息维护'!I119 -> 0 | AR9: ='0信息维护'!I125 -> 0 | AS9: =SUM(AL9:AR9) -> 100
A10: 1 | B10: 软件工程 | C10: 人工智能学部22级5班 | D10: 180202041 | E10: 林振杨 | F10: 30 | G10: 50 | M10: =SUM(F10:L10) -> 80 | Q10: 73 | U10: =SUM(N10:T10) -> 73 | AC10: =SUM(V10:AB10) -> 0 | AK10: =SUM(AD10:AJ10) -> 0 | AL10: 28 | AM10: 20 | AN10: 14 | AS10: =SUM(AL10:AR10) -> 62
A11: 2 | B11: 软件工程 | C11: 人工智能学部22级5班 | D11: 180301007 | E11: 刘彪 | F11: 40 | G11: 60 | M11: =SUM(F11:L11) -> 100 | Q11: 83 | U11: =SUM(N11:T11) -> 83 | AC11: =SUM(V11:AB11) -> 0 | AK11: =SUM(AD11:AJ11) -> 0 | AL11: 30 | AM11: 24 | AN11: 19 | AS11: =SUM(AL11:AR11) -> 73
A12: 3 | B12: 软件工程 | C12: 人工智能学部20级3班 | D12: 180301010 | E12: 童祉昂 | F12: 40 | G12: 60 | M12: =SUM(F12:L12) -> 100 | Q12: 60 | U12: =SUM(N12:T12) -> 60 | AC12: =SUM(V12:AB12) -> 0 | AK12: =SUM(AD12:AJ12) -> 0 | AL12: 34 | AM12: 25 | AN12: 19 | AS12: =SUM(AL12:AR12) -> 78
A13: 4 | B13: 软件工程 | C13: 人工智能学部22级5班 | D13: 180301042 | E13: 覃朝雄 | F13: 40 | G13: 60 | M13: =SUM(F13:L13) -> 100 | Q13: 75 | U13: =SUM(N13:T13) -> 75 | AC13: =SUM(V13:AB13) -> 0 | AK13: =SUM(AD13:AJ13) -> 0 | AL13: 34 | AM13: 21 | AN13: 20 | AS13: =SUM(AL13:AR13) -> 75
A14: 5 | B14: 软件工程 | C14: 人工智能学部22级5班 | D14: 190301001 | E14: 温佳洛 | F14: 35 | G14: 55 | M14: =SUM(F14:L14) -> 90 | Q14: 77 | U14: =SUM(N14:T14) -> 77 | AC14: =SUM(V14:AB14) -> 0 | AK14: =SUM(AD14:AJ14) -> 0 | AL14: 22 | AM14: 7 | AN14: 17 | AS14: =SUM(AL14:AR14) -> 46
A15: 6 | B15: 软件工程 | C15: 人工智能学部22级5班 | D15: 190301002 | E15: 周涛 | F15: 40 | G15: 60 | M15: =SUM(F15:L15) -> 100 | Q15: 87 | U15: =SUM(N15:T15) -> 87 | AC15: =SUM(V15:AB15) -> 0 | AK15: =SUM(AD15:AJ15) -> 0 | AL15: 32 | AM15: 30 | AN15: 25 | AS15: =SUM(AL15:AR15) -> 87
A16: 7 | B16: 软件工程 | C16: 人工智能学部22级5班 | D16: 190301003 | E16: 何中尉 | F16: 40 | G16: 60 | M16: =SUM(F16:L16) -> 100 | Q16: 85 | U16: =SUM(N16:T16) -> 85 | AC16: =SUM(V16:AB16) -> 0 | AK16: =SUM(AD16:AJ16) -> 0 | AL16: 28 | AM16: 18 | AN16: 20 | AS16: =SUM(AL16:AR16) -> 66
A17: 8 | B17: 软件工程 | C17: 人工智能学部20级3班 | D17: 190301004 | E17: 王华鹏 | F17: 0 | G17: 0 | M17: =SUM(F17:L17) -> 0 | Q17: 0 | U17: =SUM(N17:T17) -> 0 | AC17: =SUM(V17:AB17) -> 0 | AK17: =SUM(AD17:AJ17) -> 0 | AL17: 18 | AM17: 14 | AN17: 8 | AS17: =SUM(AL17:AR17) -> 40
A18: 9 | B18: 软件工程 | C18: 人工智能学部22级5班 | D18: 190301005 | E18: 袁竹 | F18: 40 | G18: 60 | M18: =SUM(F18:L18) -> 100 | Q18: 85 | U18: =SUM(N18:T18) -> 85 | AC18: =SUM(V18:AB18) -> 0 | AK18: =SUM(AD18:AJ18) -> 0 | AL18: 28 | AM18: 20 | AN18: 19 | AS18: =SUM(AL18:AR18) -> 67
A19: 10 | B19: 软件工程 | C19: 人工智能学部22级5班 | D19: 190301006 | E19: 苟晨雨 | F19: 35 | G19: 55 | M19: =SUM(F19:L19) -> 90 | Q19: 83 | U19: =SUM(N19:T19) -> 83 | AC19: =SUM(V19:AB19) -> 0 | AK19: =SUM(AD19:AJ19) -> 0 | AL19: 30 | AM19: 20 | AN19: 19 | AS19: =SUM(AL19:AR19) -> 69
A20: 11 | B20: 软件工程 | C20: 人工智能学部22级5班 | D20: 190301007 | E20: 夏婧姣 | F20: 35 | G20: 45 | M20: =SUM(F20:L20) -> 80 | Q20: 75 | U20: =SUM(N20:T20) -> 75 | AC20: =SUM(V20:AB20) -> 0 | AK20: =SUM(AD20:AJ20) -> 0 | AL20: 16 | AM20: 17 | AN20: 10 | AS20: =SUM(AL20:AR20) -> 43
A21: 12 | B21: 软件工程 | C21: 人工智能学部22级5班 | D21: 190301008 | E21: 王思皓 | F21: 35 | G21: 45 | M21: =SUM(F21:L21) -> 80 | Q21: 70 | U21: =SUM(N21:T21) -> 70 | AC21: =SUM(V21:AB21) -> 0 | AK21: =SUM(AD21:AJ21) -> 0 | AL21: 22 | AM21: 6 | AN21: 10 | AS21: =SUM(AL21:AR21) -> 38
... A81: 72 | B81: 软件工程 | C81: 人工智能学部22级5班 | D81: 190706029 | E81: 谢玉婷 | F81: 40 | G81: 60 | M81: =SUM(F81:L81) -> 100 | Q81: 82 | U81: =SUM(N81:T81) -> 82 | AC81: =SUM(V81:AB81) -> 0 | AK81: =SUM(AD81:AJ81) -> 0 | AL81: 25 | AM81: 22 | AN81: 18 | AS81: =SUM(AL81:AR81) -> 65
A82: 73 | B82: 软件工程 | C82: 人工智能学部22级5班 | D82: 190706030 | E82: 魏雨婷 | F82: 40 | G82: 60 | M82: =SUM(F82:L82) -> 100 | Q82: 87 | U82: =SUM(N82:T82) -> 87 | AL82: 26 | AM82: 18 | AN82: 14 | AS82: =SUM(AL82:AR82) -> 58
A83: 74 | B83: 软件工程 | C83: 人工智能学部22级6班 | D83: 210110106 | E83: 田磊 | F83: 34 | G83: 51 | M83: 85 | Q83: 79 | U83: 79 | AL83: 22 | AM83: 17 | AN83: 20 | AS83: 59
A84: 75 | B84: 软件工程 | C84: 人工智能学部22级6班 | D84: 210402111 | E84: 汪博伦 | F84: 32 | G84: 50 | M84: 82 | Q84: 82 | U84: 82 | AL84: 22 | AM84: 11 | AN84: 15 | AS84: 48
A85: 76 | B85: 软件工程 | C85: 人工智能学部22级6班 | D85: 210402112 | E85: 李乐斌 | F85: 34 | G85: 51 | M85: 85 | Q85: 74 | U85: 74 | AL85: 24 | AM85: 17 | AN85: 20 | AS85: 61
A86: 77 | B86: 软件工程 | C86: 人工智能学部22级6班 | D86: 210504123 | E86: 陈小愉 | F86: 32 | G86: 48 | M86: 80 | Q86: 72 | U86: 72 | AL86: 15 | AM86: 13 | AN86: 11 | AS86: 39
A87: 78 | B87: 软件工程 | C87: 人工智能学部22级6班 | D87: 220106101 | E87: 伍海涵 | F87: 32 | G87: 48 | M87: 80 | Q87: 79 | U87: 79 | AL87: 13 | AM87: 19 | AN87: 14 | AS87: 46
A88: 79 | B88: 软件工程 | C88: 人工智能学部22级6班 | D88: 220106102 | E88: 周雍丁 | F88: 34 | G88: 52 | M88: 86 | Q88: 82 | U88: 82 | AL88: 30 | AM88: 23 | AN88: 23 | AS88: 76
A89: 80 | B89: 软件工程 | C89: 人工智能学部22级6班 | D89: 220106103 | E89: 李玲 | F89: 32 | G89: 48 | M89: 80 | Q89: 73 | U89: 73 | AL89: 28 | AM89: 17 | AN89: 20 | AS89: 65
A90: 81 | B90: 软件工程 | C90: 人工智能学部22级6班 | D90: 220106104 | E90: 刘川 | F90: 34 | G90: 53 | M90: 87 | Q90: 85 | U90: 85 | AL90: 28 | AM90: 22 | AN90: 25 | AS90: 75
A91: 82 | B91: 软件工程 | C91: 人工智能学部22级6班 | D91: 220106105 | E91: 王瑶 | F91: 34 | G91: 51 | M91: 85 | Q91: 75 | U91: 75 | AL91: 25 | AM91: 12 | AN91: 12 | AS91: 49
A92: 83 | B92: 软件工程 | C92: 人工智能学部22级6班 | D92: 220106106 | E92: 吴耀东 | F92: 34 | G92: 51 | M92: 85 | Q92: 89 | U92: 89 | AL92: 25 | AM92: 13 | AN92: 22 | AS92: 60
A93: 84 | B93: 软件工程 | C93: 人工智能学部22级6班 | D93: 220106107 | E93: 段高飞 | F93: 34 | G93: 51 | M93: 85 | Q93: 84 | U93: 84 | AL93: 32 | AM93: 22 | AN93: 22 | AS93: 76
A94: 85 | B94: 软件工程 | C94: 人工智能学部22级6班 | D94: 220106108 | E94: 马明月 | F94: 32 | G94: 48 | M94: 80 | Q94: 82 | U94: 82 | AL94: 24 | AM94: 21 | AN94: 14 | AS94: 59
... A150: 141 | B150: 软件工程 | C150: 人工智能学部22级6班 | D150: 221307136 | E150: 肖杰文 | F150: 34 | G150: 51 | M150: 85 | Q150: 82 | U150: 82 | AL150: 24 | AM150: 22 | AN150: 21 | AS150: 67

Sheet 2间接评价
A1: 课程目标间接评价
A2: 课程： | B2: ='0信息维护'!D3 -> 数据结构与算法 | D2: 课程编码： | E2: ='0信息维护'!M3 -> N19ZY11005
A3: 专业： | B3: ='0信息维护'!M8 -> 软件工程 | D3: 班级： | E3: ='0信息维护'!M5 -> 计算机学院2022级5、6班
A4: 开课学部（院）： | B4: ='0信息维护'!D8 -> 人工智能与大数据学部 | D4: 任课教师： | E4: ='0信息维护'!D7 -> 任春华、段少松
A6: 学生问卷调查结果 | C6: (单位：人) | D6: 占比 | E6: ='0信息维护'!E45 -> 1
A7: 课程目标 | B7: 完全达成（A） | C7: 达成（B） | D7: 基本达成（C） | E7: 较低达成（D） | F7: 未达成（E） | G7: 达成度
B8: 赋值1 | C8: 赋值0.8 | D8: 赋值0.6 | E8: 赋值0.4 | F8: 赋值0.2
A9: 课程目标1 | B9: 118 | C9: 11 | D9: 12 | E9: 0 | F9: 0 | G9: =IF(B9+C9+D9+E9+F9=0,0,1*(B9/(B9+C9+D9+E9+F9))+0.8*(C9/(B9+C9+D9+E9+F9))+0.6*(D9/(B9+C9+D9+E9+F9))+0.4*(E9/(B9+C9+D9+E9+F9))+0.2*(F9/(B9+C9+D9+E9+F9))) -> 0.95035461
A10: 课程目标2 | B10: 122 | C10: 15 | D10: 3 | E10: 1 | F10: 0 | G10: =IF(B10+C10+D10+E10+F10=0,0,1*(B10/(B10+C10+D10+E10+F10))+0.8*(C10/(B10+C10+D10+E10+F10))+0.6*(D10/(B10+C10+D10+E10+F10))+0.4*(E10/(B10+C10+D10+E10+F10))+0.2*(F10/(B10+C10+D10+E10+F10))) -> 0.96595745
A11: 课程目标3 | B11: 123 | C11: 10 | D11: 4 | E11: 3 | F11: 1 | G11: =IF(B11+C11+D11+E11+F11=0,0,1*(B11/(B11+C11+D11+E11+F11))+0.8*(C11/(B11+C11+D11+E11+F11))+0.6*(D11/(B11+C11+D11+E11+F11))+0.4*(E11/(B11+C11+D11+E11+F11))+0.2*(F11/(B11+C11+D11+E11+F11))) -> 0.95602837
A12: 课程目标4 | B12: 124 | C12: 9 | D12: 7 | E12: 1 | G12: =IF(B12+C12+D12+E12+F12=0,0,1*(B12/(B12+C12+D12+E12+F12))+0.8*(C12/(B12+C12+D12+E12+F12))+0.6*(D12/(B12+C12+D12+E12+F12))+0.4*(E12/(B12+C12+D12+E12+F12))+0.2*(F12/(B12+C12+D12+E12+F12))) -> 0.96312057
A13: 课程目标5 | G13: =IF(B13+C13+D13+E13+F13=0,0,1*(B13/(B13+C13+D13+E13+F13))+0.8*(C13/(B13+C13+D13+E13+F13))+0.6*(D13/(B13+C13+D13+E13+F13))+0.4*(E13/(B13+C13+D13+E13+F13))+0.2*(F13/(B13+C13+D13+E13+F13))) -> 0
A14: 课程目标6 | G14: =IF(B14+C14+D14+E14+F14=0,0,1*(B14/(B14+C14+D14+E14+F14))+0.8*(C14/(B14+C14+D14+E14+F14))+0.6*(D14/(B14+C14+D14+E14+F14))+0.4*(E14/(B14+C14+D14+E14+F14))+0.2*(F14/(B14+C14+D14+E14+F14))) -> 0
A15: 课程目标7 | G15: =IF(B15+C15+D15+E15+F15=0,0,1*(B15/(B15+C15+D15+E15+F15))+0.8*(C15/(B15+C15+D15+E15+F15))+0.6*(D15/(B15+C15+D15+E15+F15))+0.4*(E15/(B15+C15+D15+E15+F15))+0.2*(F15/(B15+C15+D15+E15+F15))) -> 0
A17: ='0信息维护'!I44 -> 其它 | D17: 占比 | E17: ='0信息维护'!I45 -> 0
A18: 课程目标 | B18: 完全达成（A） | C18: 达成（B） | D18: 基本达成（C） | E18: 较低达成（D） | F18: 未达成（E） | G18: 达成度
B19: 赋值1 | C19: 赋值0.8 | D19: 赋值0.6 | E19: 赋值0.4 | F19: 赋值0.2
A20: 课程目标1 | G20: =IF(B20+C20+D20+E20+F20=0,0,1*(B20/(B20+C20+D20+E20+F20))+0.8*(C20/(B20+C20+D20+E20+F20))+0.6*(D20/(B20+C20+D20+E20+F20))+0.4*(E20/(B20+C20+D20+E20+F20))+0.2*(F20/(B20+C20+D20+E20+F20))) -> 0
A21: 课程目标2 | G21: =IF(B21+C21+D21+E21+F21=0,0,1*(B21/(B21+C21+D21+E21+F21))+0.8*(C21/(B21+C21+D21+E21+F21))+0.6*(D21/(B21+C21+D21+E21+F21))+0.4*(E21/(B21+C21+D21+E21+F21))+0.2*(F21/(B21+C21+D21+E21+F21))) -> 0
A22: 课程目标3 | G22: =IF(B22+C22+D22+E22+F22=0,0,1*(B22/(B22+C22+D22+E22+F22))+0.8*(C22/(B22+C22+D22+E22+F22))+0.6*(D22/(B22+C22+D22+E22+F22))+0.4*(E22/(B22+C22+D22+E22+F22))+0.2*(F22/(B22+C22+D22+E22+F22))) -> 0
A23: 课程目标4 | G23: =IF(B23+C23+D23+E23+F23=0,0,1*(B23/(B23+C23+D23+E23+F23))+0.8*(C23/(B23+C23+D23+E23+F23))+0.6*(D23/(B23+C23+D23+E23+F23))+0.4*(E23/(B23+C23+D23+E23+F23))+0.2*(F23/(B23+C23+D23+E23+F23))) -> 0
A24: 课程目标5 | G24: =IF(B24+C24+D24+E24+F24=0,0,1*(B24/(B24+C24+D24+E24+F24))+0.8*(C24/(B24+C24+D24+E24+F24))+0.6*(D24/(B24+C24+D24+E24+F24))+0.4*(E24/(B24+C24+D24+E24+F24))+0.2*(F24/(B24+C24+D24+E24+F24))) -> 0
A25: 课程目标6 | G25: =IF(B25+C25+D25+E25+F25=0,0,1*(B25/(B25+C25+D25+E25+F25))+0.8*(C25/(B25+C25+D25+E25+F25))+0.6*(D25/(B25+C25+D25+E25+F25))+0.4*(E25/(B25+C25+D25+E25+F25))+0.2*(F25/(B25+C25+D25+E25+F25))) -> 0
A26: 课程目标7 | G26: =IF(B26+C26+D26+E26+F26=0,0,1*(B26/(B26+C26+D26+E26+F26))+0.8*(C26/(B26+C26+D26+E26+F26))+0.6*(D26/(B26+C26+D26+E26+F26))+0.4*(E26/(B26+C26+D26+E26+F26))+0.2*(F26/(B26+C26+D26+E26+F26))) -> 0
A28: 课程目标间接评价结果
A29: 评价主体 | B29: ='0信息维护'!E44 -> 学生调查问卷 | D29: ='0信息维护'!I44 -> 其它 | F29: 达成度
A30: 课程目标1 | B30: =G9 -> 0.95035461 | D30: =G20 -> 0 | F30: =B30*$E$6+D30*$E$17 -> 0.95035461
A31: 课程目标2 | B31: =G10 -> 0.96595745 | D31: =G21 -> 0 | F31: =B31*$E$6+D31*$E$17 -> 0.96595745
A32: 课程目标3 | B32: =G11 -> 0.95602837 | D32: =G22 -> 0 | F32: =B32*$E$6+D32*$E$17 -> 0.95602837
A33: 课程目标4 | B33: =G12 -> 0.96312057 | D33: =G23 -> 0 | F33: =B33*$E$6+D33*$E$17 -> 0.96312057
A34: 课程目标5 | B34: =G13 -> 0 | D34: =G24 -> 0 | F34: =B34*$E$6+D34*$E$17 -> 0
A35: 课程目标6 | B35: =G14 -> 0 | D35: =G25 -> 0 | F35: =B35*$E$6+D35*$E$17 -> 0
A36: 课程目标7 | B36: =G15 -> 0 | D36: =G26 -> 0 | F36: =B36*$E$6+D36*$E$17 -> 0

Sheet 3课程达成度分析报告
A1: ="《"&D4&"》" -> 《数据结构与算法》
A2: 课程目标达成度评价报告
A3: 一、课程基本信息
A4: 课程名称 | D4: ='0信息维护'!D3 -> 数据结构与算法 | K4: 课程编码 | P4: ='0信息维护'!M3 -> N19ZY11005
A5: 课程类别 | D5: ='0信息维护'!D4 -> 专业核心必修课程 | K5: 学时/学分 | P5: ='0信息维护'!M4 -> 96/5
A6: 开课学期 | D6: ='0信息维护'!D5 -> 2023-2024-2 | K6: 授课对象 | P6: ='0信息维护'!M5 -> 计算机学院2022级5、6班
A7: 选课人数 | D7: ='0信息维护'!D6 -> 141 | K7: 参评人数 | P7: ='0信息维护'!M6 -> 141
A8: 任课教师 | D8: ='0信息维护'!D7 -> 任春华、段少松 | K8: 课程责任人 | P8: ='0信息维护'!M7 -> 任春华老师
A10: 二、课程目标与毕业要求的对应关系
A11: 毕业要求 课程目标 | F11: 支撑的毕业要求指标点 | T11: 支撑强度
A12: ='0信息维护'!A12 -> 课程总目标 | B12: ='0信息维护'!B12 -> 课程目标1 | F12: ='0信息维护'!E12 -> 学生具备分析线性表、栈和队列、串、数组和广义表、树和二叉树、图等各种基本数据结构的能力；能够针对具体问题，通过定义抽象数学模型、算法并求解。 | T12: L
B13: ='0信息维护'!B13 -> 课程目标2 | F13: ='0信息维护'!E13 -> 针对工程应用问题，学生能够利用抽象数据结构思维的能力，比较和综合各种方案在逻辑结构、存储结构的优劣。 | T13: H
B14: ='0信息维护'!B14 -> 课程目标3 | F14: ='0信息维护'!E14 -> 学生能够运用数据结构与算法的基本原理，识别和判断复杂软件工程问题中数据结构使用和算法选择的关键环节。 | T14: H
B15: ='0信息维护'!B15 -> 课程目标4 | F15: ='0信息维护'!E15 -> 学生结合具体应用案例，能够认识到有多种逻辑结构和存储结构可供选择，通过网络、文献、大模型等方法寻求应用案例的解决方案。 | T15: L
B16: ='0信息维护'!B16 -> 课程目标5 | F16: ='0信息维护'!E16 -> 0 | T16: M
B17: ='0信息维护'!B17 -> 课程目标6 | F17: ='0信息维护'!E17 -> 0 | T17: ='0信息维护'!P17 -> 0
B18: ='0信息维护'!B18 -> 课程目标7 | F18: ='0信息维护'!E18 -> 0 | T18: ='0信息维护'!P18 -> 0
A20: 三、课程目标评价方式
A21: 评价 方式 课程 分目标 | C21: 直接评价 | R21: 间接评价
C22: 过程性评价 | O22: ='0信息维护'!I34 -> 结果性评价 | R22: ='0信息维护'!E44 -> 学生调查问卷 | T22: ='0信息维护'!I44 -> 其它
C23: ='0信息维护'!E24 -> 平时作业 | F23: ='0信息维护'!I24 -> 实验考核 | I23: ='0信息维护'!L24 -> 0 | L23: ='0信息维护'!O24 -> 0
A24: ='0信息维护'!A25 -> 课程目标1 | C24: ='0信息维护'!$S25*'0信息维护'!$E35*'0信息维护'!$E55 -> 0.4 | F24: ='0信息维护'!$T25*'0信息维护'!$E35*'0信息维护'!$E55 -> 0 | I24: ='0信息维护'!$U25*'0信息维护'!$E35*'0信息维护'!$E55 -> 0 | L24: ='0信息维护'!$V25*'0信息维护'!$E35*'0信息维护'!$E55 -> 0 | O24: ='0信息维护'!I35*'0信息维护'!E55 -> 0.4 | R24: ='0信息维护'!E45*'0信息维护'!I55 -> 0.2 | T24: ='0信息维护'!I45*'0信息维护'!I55 -> 0
A25: ='0信息维护'!A26 -> 课程目标2 | C25: ='0信息维护'!$S26*'0信息维护'!$E36*'0信息维护'!$E56 -> 0.4 | F25: ='0信息维护'!$T26*'0信息维护'!$E36*'0信息维护'!$E56 -> 0 | I25: ='0信息维护'!$U26*'0信息维护'!$E36*'0信息维护'!$E56 -> 0 | L25: ='0信息维护'!$V26*'0信息维护'!$E36*'0信息维护'!$E56 -> 0 | O25: ='0信息维护'!I36*'0信息维护'!E56 -> 0.4 | R25: ='0信息维护'!E46*'0信息维护'!I56 -> 0.2 | T25: ='0信息维护'!I46*'0信息维护'!I56 -> 0
A26: ='0信息维护'!A27 -> 课程目标3 | C26: ='0信息维护'!$S27*'0信息维护'!$E37*'0信息维护'!$E57 -> 0 | F26: ='0信息维护'!$T27*'0信息维护'!$E37*'0信息维护'!$E57 -> 0 | I26: ='0信息维护'!$U27*'0信息维护'!$E37*'0信息维护'!$E57 -> 0 | L26: ='0信息维护'!$V27*'0信息维护'!$E37*'0信息维护'!$E57 -> 0 | O26: ='0信息维护'!I37*'0信息维护'!E57 -> 0.8 | R26: ='0信息维护'!E47*'0信息维护'!I57 -> 0.2 | T26: ='0信息维护'!I47*'0信息维护'!I57 -> 0
A27: ='0信息维护'!A28 -> 课程目标4 | C27: ='0信息维护'!$S28*'0信息维护'!$E38*'0信息维护'!$E58 -> 0 | F27: ='0信息维护'!$T28*'0信息维护'!$E38*'0信息维护'!$E58 -> 0.8 | I27: ='0信息维护'!$U28*'0信息维护'!$E38*'0信息维护'!$E58 -> 0 | L27: ='0信息维护'!$V28*'0信息维护'!$E38*'0信息维护'!$E58 -> 0 | O27: ='0信息维护'!I38*'0信息维护'!E58 -> 0 | R27: ='0信息维护'!E48*'0信息维护'!I58 -> 0.2 | T27: ='0信息维护'!I48*'0信息维护'!I58 -> 0
A28: ='0信息维护'!A29 -> 课程目标5 | C28: ='0信息维护'!$S29*'0信息维护'!$E39*'0信息维护'!$E59 -> 0 | F28: ='0信息维护'!$T29*'0信息维护'!$E39*'0信息维护'!$E59 -> 0 | I28: ='0信息维护'!$U29*'0信息维护'!$E39*'0信息维护'!$E59 -> 0 | L28: ='0信息维护'!$V29*'0信息维护'!$E39*'0信息维护'!$E59 -> 0 | O28: ='0信息维护'!I39*'0信息维护'!E59 -> 0 | R28: ='0信息维护'!E49*'0信息维护'!I59 -> 0.2 | T28: ='0信息维护'!I49*'0信息维护'!I59 -> 0
A29: ='0信息维护'!A30 -> 课程目标6 | C29: ='0信息维护'!$S30*'0信息维护'!$E40*'0信息维护'!$E60 -> 0 | F29: ='0信息维护'!$T30*'0信息维护'!$E40*'0信息维护'!$E60 -> 0 | I29: ='0信息维护'!$U30*'0信息维护'!$E40*'0信息维护'!$E60 -> 0 | L29: ='0信息维护'!$V30*'0信息维护'!$E40*'0信息维护'!$E60 -> 0 | O29: ='0信息维护'!I40*'0信息维护'!E60 -> 0 | R29: ='0信息维护'!E50*'0信息维护'!I60 -> 0 | T29: ='0信息维护'!I50*'0信息维护'!I60 -> 0
A30: ='0信息维护'!A31 -> 课程目标7 | C30: ='0信息维护'!$S31*'0信息维护'!$E41*'0信息维护'!$E61 -> 0 | F30: ='0信息维护'!$T31*'0信息维护'!$E41*'0信息维护'!$E61 -> 0 | I30: ='0信息维护'!$U31*'0信息维护'!$E41*'0信息维护'!$E61 -> 0 | L30: ='0信息维护'!$V31*'0信息维护'!$E41*'0信息维护'!$E61 -> 0 | O30: ='0信息维护'!I41*'0信息维护'!E61 -> 0 | R30: ='0信息维护'!E51*'0信息维护'!I61 -> 0 | T30: ='0信息维护'!I51*'0信息维护'!I61 -> 0
A32: 四、考试试题对应课程分目标
A33: 课程目标1 | C33: 小题号 | D33: ='0信息维护'!C64 -> 1 | E33: ='0信息维护'!D64 -> 7 | F33: ='0信息维护'!E64 -> 8 | G33: ='0信息维护'!F64 -> 9 | H33: ='0信息维护'!G64 -> 11 | I33: ='0信息维护'!H64 -> 12 | J33: ='0信息维护'!I64 -> 16 | K33: ='0信息维护'!J64 -> 17 | ... R33: ='0信息维护'!Q64 -> 0 | S33: 合计
C34: 分值 | D34: ='0信息维护'!C65 -> 2 | E34: ='0信息维护'!D65 -> 2 | F34: ='0信息维护'!E65 -> 2 | G34: ='0信息维护'!F65 -> 2 | H34: ='0信息维护'!G65 -> 2 | I34: ='0信息维护'!H65 -> 2 | J34: ='0信息维护'!I65 -> 2 | K34: ='0信息维护'!J65 -> 2 | ... S34: ='0信息维护'!R65 -> 36
A35: 课程目标2 | C35: 小题号 | D35: ='0信息维护'!C66 -> 3 | E35: ='0信息维护'!D66 -> 6 | F35: ='0信息维护'!E66 -> 13 | G35: ='0信息维护'!F66 -> 14 | H35: ='0信息维护'!G66 -> 18 | I35: ='0信息维护'!H66 -> 19 | J35: ='0信息维护'!I66 -> 23 | K35: ='0信息维护'!J66 -> 24 | ... R35: ='0信息维护'!Q66 -> 0
C36: 分值 | D36: ='0信息维护'!C67 -> 2 | E36: ='0信息维护'!D67 -> 2 | F36: ='0信息维护'!E67 -> 2 | G36: ='0信息维护'!F67 -> 2 | H36: ='0信息维护'!G67 -> 2 | I36: ='0信息维护'!H67 -> 2 | J36: ='0信息维护'!I67 -> 2 | K36: ='0信息维护'!J67 -> 2 | ... S36: ='0信息维护'!R67 -> 30
A37: 课程目标3 | C37: 小题号 | D37: ='0信息维护'!C68 -> 2 | E37: ='0信息维护'!D68 -> 4 | F37: ='0信息维护'!E68 -> 5 | G37: ='0信息维护'!F68 -> 10 | H37: ='0信息维护'!G68 -> 15 | I37: ='0信息维护'!H68 -> 21 | J37: ='0信息维护'!I68 -> 22 | K37: ='0信息维护'!J68 -> 25 | ... R37: ='0信息维护'!Q68 -> 0
C38: 分值 | D38: ='0信息维护'!C69 -> 2 | E38: ='0信息维护'!D69 -> 2 | F38: ='0信息维护'!E69 -> 2 | G38: ='0信息维护'!F69 -> 2 | H38: ='0信息维护'!G69 -> 2 | I38: ='0信息维护'!H69 -> 2 | J38: ='0信息维护'!I69 -> 2 | K38: ='0信息维护'!J69 -> 2 | ... S38: ='0信息维护'!R69 -> 34
A39: 课程目标4 | C39: 小题号 | D39: ='0信息维护'!C70 -> 0 | E39: ='0信息维护'!D70 -> 0 | F39: ='0信息维护'!E70 -> 0 | G39: ='0信息维护'!F70 -> 0 | H39: ='0信息维护'!G70 -> 0 | I39: ='0信息维护'!H70 -> 0 | J39: ='0信息维护'!I70 -> 0 | K39: ='0信息维护'!J70 -> 0 | ... R39: ='0信息维护'!Q70 -> 0
C40: 分值 | D40: ='0信息维护'!C71 -> 0 | E40: ='0信息维护'!D71 -> 0 | F40: ='0信息维护'!E71 -> 0 | G40: ='0信息维护'!F71 -> 0 | H40: ='0信息维护'!G71 -> 0 | I40: ='0信息维护'!H71 -> 0 | J40: ='0信息维护'!I71 -> 0 | K40: ='0信息维护'!J71 -> 0 | ... S40: ='0信息维护'!R71 -> 0
A41: 课程目标5 | C41: 小题号 | D41: ='0信息维护'!C72 -> 0 | E41: ='0信息维护'!D72 -> 0 | F41: ='0信息维护'!E72 -> 0 | G41: ='0信息维护'!F72 -> 0 | H41: ='0信息维护'!G72 -> 0 | I41: ='0信息维护'!H72 -> 0 | J41: ='0信息维护'!I72 -> 0 | K41: ='0信息维护'!J72 -> 0 | ... R41: ='0信息维护'!Q72 -> 0
C42: 分值 | D42: ='0信息维护'!C73 -> 0 | E42: ='0信息维护'!D73 -> 0 | F42: ='0信息维护'!E73 -> 0 | G42: ='0信息维护'!F73 -> 0 | H42: ='0信息维护'!G73 -> 0 | I42: ='0信息维护'!H73 -> 0 | J42: ='0信息维护'!I73 -> 0 | K42: ='0信息维护'!J73 -> 0 | ... S42: ='0信息维护'!R73 -> 0
A43: 课程目标6 | C43: 小题号 | D43: ='0信息维护'!C74 -> 0 | E43: ='0信息维护'!D74 -> 0 | F43: ='0信息维护'!E74 -> 0 | G43: ='0信息维护'!F74 -> 0 | H43: ='0信息维护'!G74 -> 0 | I43: ='0信息维护'!H74 -> 0 | J43: ='0信息维护'!I74 -> 0 | K43: ='0信息维护'!J74 -> 0 | ... R43: ='0信息维护'!Q74 -> 0
...

Sheet 4学生课程目标达成度
A1: 基于直接评价的学生课程目标达成度
A2: 课程信息 学生信息 | D2: 课程分目标 | E2: 评价方式1 | F2: 评价方式2 | G2: 评价方式3 | H2: 评价方式4 | I2: 评价方式5 | J2: 分目标达成度 | K2: 总目标达成度
E3: ='0信息维护'!E24 -> 平时作业 | F3: ='0信息维护'!I24 -> 实验考核 | G3: ='0信息维护'!L24 -> 0 | H3: ='0信息维护'!O24 -> 0 | I3: ='0信息维护'!I34 -> 结果性评价
A5: 1 | B5: =OFFSET('1课程考核方式及成绩组成'!$D$10,(ROW(B5)-5)/7,) -> 180202041 | C5: =OFFSET('1课程考核方式及成绩组成'!$E$10,(ROW(C5)-5)/7,) -> 林振杨 | D5: ='0信息维护'!A$25 -> 课程目标1 | E5: =OFFSET('1课程考核方式及成绩组成'!$F$10,(ROW(E5)-5)/7,MOD((ROW(E5)-5),7)) -> 30 | F5: =OFFSET('1课程考核方式及成绩组成'!$N$10,(ROW(F5)-5)/7,MOD((ROW(F5)-5),7)) -> 0 | G5: =OFFSET('1课程考核方式及成绩组成'!$V$10,(ROW(G5)-5)/7,MOD((ROW(G5)-5),7)) -> 0 | H5: =OFFSET('1课程考核方式及成绩组成'!$AD$10,(ROW(H5)-5)/7,MOD((ROW(H5)-5),7)) -> 0 | I5: =OFFSET('1课程考核方式及成绩组成'!$AL$10,(ROW(I5)-5)/7,MOD((ROW(I5)-5),7)) -> 28 | J5: =IF('0信息维护'!$I$85=0,0,E5/('0信息维护'!$I$85)*'0信息维护'!$E$35*'0信息维护'!$S$25)+IF('0信息维护'!$I$86=0,0,F5/('0信息维护'!$I$86)*'0信息维护'!$E$35*'0信息维护'!$T$25)+IF('0信息维护'!$I$87=0,0,G5/('0信息维护'!$I$87)*'0信息维护'!$E$35*'0信息维护'!$U$25)+IF('0信息维护'!$I$88=0,0,H5/('0信息维护'!$I$88)*'0信息维护'!$E$35*'0信息维护'!$V$25)+IF('0信息维护'!$I$89=0,0,I5/'0信息维护'!$I$89*'0信息维护'!$I$35) -> 0.76388889 | K5: =J5*'0信息维护'!$D$132+J6*'0信息维护'!$D$133+J7*'0信息维护'!$D$134+J8*'0信息维护'!$D$135+J9*'0信息维护'!$D$136+J10*'0信息维护'!$D$137+J11*'0信息维护'!$D$138 -> 0.66152451
D6: ='0信息维护'!A$26 -> 课程目标2 | E6: =OFFSET('1课程考核方式及成绩组成'!$F$10,(ROW(E6)-5)/7,MOD((ROW(E6)-5),7)) -> 50 | F6: =OFFSET('1课程考核方式及成绩组成'!$N$10,(ROW(F6)-5)/7,MOD((ROW(F6)-5),7)) -> 0 | G6: =OFFSET('1课程考核方式及成绩组成'!$V$10,(ROW(G6)-5)/7,MOD((ROW(G6)-5),7)) -> 0 | H6: =OFFSET('1课程考核方式及成绩组成'!$AD$10,(ROW(H6)-5)/7,MOD((ROW(H6)-5),7)) -> 0 | I6: =OFFSET('1课程考核方式及成绩组成'!$AL$10,(ROW(I6)-5)/7,MOD((ROW(I6)-5),7)) -> 20 | J6: =IF('0信息维护'!$I$91=0,0,E6/('0信息维护'!$I$91)*'0信息维护'!$S$26*'0信息维护'!$E$36)+IF('0信息维护'!$I$92=0,0,F6/('0信息维护'!$I$92)*'0信息维护'!$T$26*'0信息维护'!$E$36)+IF('0信息维护'!$I$93=0,0,G6/('0信息维护'!$I$93)*'0信息维护'!$U$26*'0信息维护'!$E$36)+IF('0信息维护'!$I$94=0,0,H6/('0信息维护'!$I$94)*'0信息维护'!$V$26*'0信息维护'!$E$36)+IF('0信息维护'!$I$95=0,0,I6/'0信息维护'!$I$95*'0信息维护'!$I$36) -> 0.75
D7: ='0信息维护'!A$27 -> 课程目标3 | E7: =OFFSET('1课程考核方式及成绩组成'!$F$10,(ROW(E7)-5)/7,MOD((ROW(E7)-5),7)) -> 0 | F7: =OFFSET('1课程考核方式及成绩组成'!$N$10,(ROW(F7)-5)/7,MOD((ROW(F7)-5),7)) -> 0 | G7: =OFFSET('1课程考核方式及成绩组成'!$V$10,(ROW(G7)-5)/7,MOD((ROW(G7)-5),7)) -> 0 | H7: =OFFSET('1课程考核方式及成绩组成'!$AD$10,(ROW(H7)-5)/7,MOD((ROW(H7)-5),7)) -> 0 | I7: =OFFSET('1课程考核方式及成绩组成'!$AL$10,(ROW(I7)-5)/7,MOD((ROW(I7)-5),7)) -> 14 | J7: =IF('0信息维护'!$I$97=0,0,E7/('0信息维护'!$I$97)*'0信息维护'!$E$37*'0信息维护'!$S$27)+IF('0信息维护'!$I$98=0,0,F7/('0信息维护'!$I$98)*'0信息维护'!$E$37*'0信息维护'!$T$27)+IF('0信息维护'!$I$99=0,0,G7/('0信息维护'!$I$99)*'0信息维护'!$E$37*'0信息维护'!$U$27)+IF('0信息维护'!$I$100=0,0,H7/('0信息维护'!$I$100)*'0信息维护'!$E$37*'0信息维护'!$V$27)+IF('0信息维护'!$I$101=0,0,I7/'0信息维护'!$I$101*'0信息维护'!$I$37) -> 0.41176471
D8: ='0信息维护'!A$28 -> 课程目标4 | E8: =OFFSET('1课程考核方式及成绩组成'!$F$10,(ROW(E8)-5)/7,MOD((ROW(E8)-5),7)) -> 0 | F8: =OFFSET('1课程考核方式及成绩组成'!$N$10,(ROW(F8)-5)/7,MOD((ROW(F8)-5),7)) -> 73 | G8: =OFFSET('1课程考核方式及成绩组成'!$V$10,(ROW(G8)-5)/7,MOD((ROW(G8)-5),7)) -> 0 | H8: =OFFSET('1课程考核方式及成绩组成'!$AD$10,(ROW(H8)-5)/7,MOD((ROW(H8)-5),7)) -> 0 | I8: =OFFSET('1课程考核方式及成绩组成'!$AL$10,(ROW(I8)-5)/7,MOD((ROW(I8)-5),7)) -> 0 | J8: =IF('0信息维护'!$I$103=0,0,E8/('0信息维护'!$I$103)*'0信息维护'!$E$38*'0信息维护'!$S$28)+IF('0信息维护'!$I$104=0,0,F8/('0信息维护'!$I$104)*'0信息维护'!$E$38*'0信息维护'!$T$28)+IF('0信息维护'!$I$105=0,0,G8/('0信息维护'!$I$105)*'0信息维护'!$E$38*'0信息维护'!$U$28)+IF('0信息维护'!$I$106=0,0,H8/('0信息维护'!$I$106)*'0信息维护'!$E$38*'0信息维护'!$V$28)+IF('0信息维护'!$I$107=0,0,I8/'0信息维护'!$I$107*'0信息维护'!$I$38) -> 0.73
D9: ='0信息维护'!A$29 -> 课程目标5 | E9: =OFFSET('1课程考核方式及成绩组成'!$F$10,(ROW(E9)-5)/7,MOD((ROW(E9)-5),7)) -> 0 | F9: =OFFSET('1课程考核方式及成绩组成'!$N$10,(ROW(F9)-5)/7,MOD((ROW(F9)-5),7)) -> 0 | G9: =OFFSET('1课程考核方式及成绩组成'!$V$10,(ROW(G9)-5)/7,MOD((ROW(G9)-5),7)) -> 0 | H9: =OFFSET('1课程考核方式及成绩组成'!$AD$10,(ROW(H9)-5)/7,MOD((ROW(H9)-5),7)) -> 0 | I9: =OFFSET('1课程考核方式及成绩组成'!$AL$10,(ROW(I9)-5)/7,MOD((ROW(I9)-5),7)) -> 0 | J9: =IF('0信息维护'!$I$109=0,0,E9/('0信息维护'!$I$109)*'0信息维护'!$E$39*'0信息维护'!$S$29)+IF('0信息维护'!$I$110=0,0,F9/('0信息维护'!$I$110)*'0信息维护'!$E$39*'0信息维护'!$T$29)+IF('0信息维护'!$I$111=0,0,G9/('0信息维护'!$I$111)*'0信息维护'!$E$39*'0信息维护'!$U$29)+IF('0信息维护'!$I$112=0,0,H9/('0信息维护'!$I$112)*'0信息维护'!$E$39*'0信息维护'!$V$29)+IF('0信息维护'!$I$113=0,0,I9/'0信息维护'!$I$113*'0信息维护'!$I$39) -> 0
D10: ='0信息维护'!A$30 -> 课程目标6 | E10: =OFFSET('1课程考核方式及成绩组成'!$F$10,(ROW(E10)-5)/7,MOD((ROW(E10)-5),7)) -> 0 | F10: =OFFSET('1课程考核方式及成绩组成'!$N$10,(ROW(F10)-5)/7,MOD((ROW(F10)-5),7)) -> 0 | G10: =OFFSET('1课程考核方式及成绩组成'!$V$10,(ROW(G10)-5)/7,MOD((ROW(G10)-5),7)) -> 0 | H10: =OFFSET('1课程考核方式及成绩组成'!$AD$10,(ROW(H10)-5)/7,MOD((ROW(H10)-5),7)) -> 0 | I10: =OFFSET('1课程考核方式及成绩组成'!$AL$10,(ROW(I10)-5)/7,MOD((ROW(I10)-5),7)) -> 0 | J10: =IF('0信息维护'!$I$115=0,0,E10/('0信息维护'!$I$115)*'0信息维护'!$E$40*'0信息维护'!$S$30)+IF('0信息维护'!$I$116=0,0,F10/('0信息维护'!$I$116)*'0信息维护'!$E$40*'0信息维护'!$T$30)+IF('0信息维护'!$I$117=0,0,G10/('0信息维护'!$I$117)*'0信息维护'!$E$40*'0信息维护'!$U$30)+IF('0信息维护'!$I$118=0,0,H10/('0信息维护'!$I$118)*'0信息维护'!$E$40*'0信息维护'!$V$30)+IF('0信息维护'!$I$119=0,0,I10/'0信息维护'!$I$119*'0信息维护'!$I$40) -> 0
D11: ='0信息维护'!A$31 -> 课程目标7 | E11: =OFFSET('1课程考核方式及成绩组成'!$F$10,(ROW(E11)-5)/7,MOD((ROW(E11)-5),7)) -> 0 | F11: =OFFSET('1课程考核方式及成绩组成'!$N$10,(ROW(F11)-5)/7,MOD((ROW(F11)-5),7)) -> 0 | G11: =OFFSET('1课程考核方式及成绩组成'!$V$10,(ROW(G11)-5)/7,MOD((ROW(G11)-5),7)) -> 0 | H11: =OFFSET('1课程考核方式及成绩组成'!$AD$10,(ROW(H11)-5)/7,MOD((ROW(H11)-5),7)) -> 0 | I11: =OFFSET('1课程考核方式及成绩组成'!$AL$10,(ROW(I11)-5)/7,MOD((ROW(I11)-5),7)) -> 0 | J11: =IF('0信息维护'!$I$121=0,0,E11/('0信息维护'!$I$121)*'0信息维护'!$E$41*'0信息维护'!$S$31)+IF('0信息维护'!$I$122=0,0,F11/('0信息维护'!$I$122)*'0信息维护'!$E$41*'0信息维护'!$T$31)+IF('0信息维护'!$I$123=0,0,G11/('0信息维护'!$I$123)*'0信息维护'!$E$41*'0信息维护'!$U$31)+IF('0信息维护'!$I$124=0,0,H11/('0信息维护'!$I$124)*'0信息维护'!$E$41*'0信息维护'!$V$31)+IF('0信息维护'!$I$125=0,0,I11/'0信息维护'!$I$125*'0信息维护'!$I$41) -> 0
A12: 2 | B12: =OFFSET('1课程考核方式及成绩组成'!$D$10,(ROW(B12)-5)/7,) -> 180301007 | C12: =OFFSET('1课程考核方式及成绩组成'!$E$10,(ROW(C12)-5)/7,) -> 刘彪 | D12: ='0信息维护'!A$25 -> 课程目标1 | E12: =OFFSET('1课程考核方式及成绩组成'!$F$10,(ROW(E12)-5)/7,MOD((ROW(E12)-5),7)) -> 40 | F12: =OFFSET('1课程考核方式及成绩组成'!$N$10,(ROW(F12)-5)/7,MOD((ROW(F12)-5),7)) -> 0 | G12: =OFFSET('1课程考核方式及成绩组成'!$V$10,(ROW(G12)-5)/7,MOD((ROW(G12)-5),7)) -> 0 | H12: =OFFSET('1课程考核方式及成绩组成'!$AD$10,(ROW(H12)-5)/7,MOD((ROW(H12)-5),7)) -> 0 | I12: =OFFSET('1课程考核方式及成绩组成'!$AL$10,(ROW(I12)-5)/7,MOD((ROW(I12)-5),7)) -> 30 | J12: =IF('0信息维护'!$I$85=0,0,E12/('0信息维护'!$I$85)*'0信息维护'!$E$35*'0信息维护'!$S$25)+IF('0信息维护'!$I$86=0,0,F12/('0信息维护'!$I$86)*'0信息维护'!$E$35*'0信息维护'!$T$25)+IF('0信息维护'!$I$87=0,0,G12/('0信息维护'!$I$87)*'0信息维护'!$E$35*'0信息维护'!$U$25)+IF('0信息维护'!$I$88=0,0,H12/('0信息维护'!$I$88)*'0信息维护'!$E$35*'0信息维护'!$V$25)+IF('0信息维护'!$I$89=0,0,I12/'0信息维护'!$I$89*'0信息维护'!$I$35) -> 0.91666667 | K12: =J12*'0信息维护'!$D$132+J13*'0信息维护'!$D$133+J14*'0信息维护'!$D$134+J15*'0信息维护'!$D$135+J16*'0信息维护'!$D$136+J17*'0信息维护'!$D$137+J18*'0信息维护'!$D$138 -> 0.79620588
D13: ='0信息维护'!A$26 -> 课程目标2 | E13: =OFFSET('1课程考核方式及成绩组成'!$F$10,(ROW(E13)-5)/7,MOD((ROW(E13)-5),7)) -> 60 | F13: =OFFSET('1课程考核方式及成绩组成'!$N$10,(ROW(F13)-5)/7,MOD((ROW(F13)-5),7)) -> 0 | G13: =OFFSET('1课程考核方式及成绩组成'!$V$10,(ROW(G13)-5)/7,MOD((ROW(G13)-5),7)) -> 0 | H13: =OFFSET('1课程考核方式及成绩组成'!$AD$10,(ROW(H13)-5)/7,MOD((ROW(H13)-5),7)) -> 0 | I13: =OFFSET('1课程考核方式及成绩组成'!$AL$10,(ROW(I13)-5)/7,MOD((ROW(I13)-5),7)) -> 24 | J13: =IF('0信息维护'!$I$91=0,0,E13/('0信息维护'!$I$91)*'0信息维护'!$S$26*'0信息维护'!$E$36)+IF('0信息维护'!$I$92=0,0,F13/('0信息维护'!$I$92)*'0信息维护'!$T$26*'0信息维护'!$E$36)+IF('0信息维护'!$I$93=0,0,G13/('0信息维护'!$I$93)*'0信息维护'!$U$26*'0信息维护'!$E$36)+IF('0信息维护'!$I$94=0,0,H13/('0信息维护'!$I$94)*'0信息维护'!$V$26*'0信息维护'!$E$36)+IF('0信息维护'!$I$95=0,0,I13/'0信息维护'!$I$95*'0信息维护'!$I$36) -> 0.9
D14: ='0信息维护'!A$27 -> 课程目标3 | E14: =OFFSET('1课程考核方式及成绩组成'!$F$10,(ROW(E14)-5)/7,MOD((ROW(E14)-5),7)) -> 0 | F14: =OFFSET('1课程考核方式及成绩组成'!$N$10,(ROW(F14)-5)/7,MOD((ROW(F14)-5),7)) -> 0 | G14: =OFFSET('1课程考核方式及成绩组成'!$V$10,(ROW(G14)-5)/7,MOD((ROW(G14)-5),7)) -> 0 | H14: =OFFSET('1课程考核方式及成绩组成'!$AD$10,(ROW(H14)-5)/7,MOD((ROW(H14)-5),7)) -> 0 | I14: =OFFSET('1课程考核方式及成绩组成'!$AL$10,(ROW(I14)-5)/7,MOD((ROW(I14)-5),7)) -> 19 | J14: =IF('0信息维护'!$I$97=0,0,E14/('0信息维护'!$I$97)*'0信息维护'!$E$37*'0信息维护'!$S$27)+IF('0信息维护'!$I$98=0,0,F14/('0信息维护'!$I$98)*'0信息维护'!$E$37*'0信息维护'!$T$27)+IF('0信息维护'!$I$99=0,0,G14/('0信息维护'!$I$99)*'0信息维护'!$E$37*'0信息维护'!$U$27)+IF('0信息维护'!$I$100=0,0,H14/('0信息维护'!$I$100)*'0信息维护'!$E$37*'0信息维护'!$V$27)+IF('0信息维护'!$I$101=0,0,I14/'0信息维护'!$I$101*'0信息维护'!$I$37) -> 0.55882353
D15: ='0信息维护'!A$28 -> 课程目标4 | E15: =OFFSET('1课程考核方式及成绩组成'!$F$10,(ROW(E15)-5)/7,MOD((ROW(E15)-5),7)) -> 0 | F15: =OFFSET('1课程考核方式及成绩组成'!$N$10,(ROW(F15)-5)/7,MOD((ROW(F15)-5),7)) -> 83 | G15: =OFFSET('1课程考核方式及成绩组成'!$V$10,(ROW(G15)-5)/7,MOD((ROW(G15)-5),7)) -> 0 | H15: =OFFSET('1课程考核方式及成绩组成'!$AD$10,(ROW(H15)-5)/7,MOD((ROW(H15)-5),7)) -> 0 | I15: =OFFSET('1课程考核方式及成绩组成'!$AL$10,(ROW(I15)-5)/7,MOD((ROW(I15)-5),7)) -> 0 | J15: =IF('0信息维护'!$I$103=0,0,E15/('0信息维护'!$I$103)*'0信息维护'!$E$38*'0信息维护'!$S$28)+IF('0信息维护'!$I$104=0,0,F15/('0信息维护'!$I$104)*'0信息维护'!$E$38*'0信息维护'!$T$28)+IF('0信息维护'!$I$105=0,0,G15/('0信息维护'!$I$105)*'0信息维护'!$E$38*'0信息维护'!$U$28)+IF('0信息维护'!$I$106=0,0,H15/('0信息维护'!$I$106)*'0信息维护'!$E$38*'0信息维护'!$V$28)+IF('0信息维护'!$I$107=0,0,I15/'0信息维护'!$I$107*'0信息维护'!$I$38) -> 0.83
D16: ='0信息维护'!A$29 -> 课程目标5 | E16: =OFFSET('1课程考核方式及成绩组成'!$F$10,(ROW(E16)-5)/7,MOD((ROW(E16)-5),7)) -> 0 | F16: =OFFSET('1课程考核方式及成绩组成'!$N$10,(ROW(F16)-5)/7,MOD((ROW(F16)-5),7)) -> 0 | G16: =OFFSET('1课程考核方式及成绩组成'!$V$10,(ROW(G16)-5)/7,MOD((ROW(G16)-5),7)) -> 0 | H16: =OFFSET('1课程考核方式及成绩组成'!$AD$10,(ROW(H16)-5)/7,MOD((ROW(H16)-5),7)) -> 0 | I16: =OFFSET('1课程考核方式及成绩组成'!$AL$10,(ROW(I16)-5)/7,MOD((ROW(I16)-5),7)) -> 0 | J16: =IF('0信息维护'!$I$109=0,0,E16/('0信息维护'!$I$109)*'0信息维护'!$E$39*'0信息维护'!$S$29)+IF('0信息维护'!$I$110=0,0,F16/('0信息维护'!$I$110)*'0信息维护'!$E$39*'0信息维护'!$T$29)+IF('0信息维护'!$I$111=0,0,G16/('0信息维护'!$I$111)*'0信息维护'!$E$39*'0信息维护'!$U$29)+IF('0信息维护'!$I$112=0,0,H16/('0信息维护'!$I$112)*'0信息维护'!$E$39*'0信息维护'!$V$29)+IF('0信息维护'!$I$113=0,0,I16/'0信息维护'!$I$113*'0信息维护'!$I$39) -> 0
D17: ='0信息维护'!A$30 -> 课程目标6 | E17: =OFFSET('1课程考核方式及成绩组成'!$F$10,(ROW(E17)-5)/7,MOD((ROW(E17)-5),7)) -> 0 | F17: =OFFSET('1课程考核方式及成绩组成'!$N$10,(ROW(F17)-5)/7,MOD((ROW(F17)-5),7)) -> 0 | G17: =OFFSET('1课程考核方式及成绩组成'!$V$10,(ROW(G17)-5)/7,MOD((ROW(G17)-5),7)) -> 0 | H17: =OFFSET('1课程考核方式及成绩组成'!$AD$10,(ROW(H17)-5)/7,MOD((ROW(H17)-5),7)) -> 0 | I17: =OFFSET('1课程考核方式及成绩组成'!$AL$10,(ROW(I17)-5)/7,MOD((ROW(I17)-5),7)) -> 0 | J17: =IF('0信息维护'!$I$115=0,0,E17/('0信息维护'!$I$115)*'0信息维护'!$E$40*'0信息维护'!$S$30)+IF('0信息维护'!$I$116=0,0,F17/('0信息维护'!$I$116)*'0信息维护'!$E$40*'0信息维护'!$T$30)+IF('0信息维护'!$I$117=0,0,G17/('0信息维护'!$I$117)*'0信息维护'!$E$40*'0信息维护'!$U$30)+IF('0信息维护'!$I$118=0,0,H17/('0信息维护'!$I$118)*'0信息维护'!$E$40*'0信息维护'!$V$30)+IF('0信息维护'!$I$119=0,0,I17/'0信息维护'!$I$119*'0信息维护'!$I$40) -> 0
D18: ='0信息维护'!A$31 -> 课程目标7 | E18: =OFFSET('1课程考核方式及成绩组成'!$F$10,(ROW(E18)-5)/7,MOD((ROW(E18)-5),7)) -> 0 | F18: =OFFSET('1课程考核方式及成绩组成'!$N$10,(ROW(F18)-5)/7,MOD((ROW(F18)-5),7)) -> 0 | G18: =OFFSET('1课程考核方式及成绩组成'!$V$10,(ROW(G18)-5)/7,MOD((ROW(G18)-5),7)) -> 0 | H18: =OFFSET('1课程考核方式及成绩组成'!$AD$10,(ROW(H18)-5)/7,MOD((ROW(H18)-5),7)) -> 0 | I18: =OFFSET('1课程考核方式及成绩组成'!$AL$10,(ROW(I18)-5)/7,MOD((ROW(I18)-5),7)) -> 0 | J18: =IF('0信息维护'!$I$121=0,0,E18/('0信息维护'!$I$121)*'0信息维护'!$E$41*'0信息维护'!$S$31)+IF('0信息维护'!$I$122=0,0,F18/('0信息维护'!$I$122)*'0信息维护'!$E$41*'0信息维护'!$T$31)+IF('0信息维护'!$I$123=0,0,G18/('0信息维护'!$I$123)*'0信息维护'!$E$41*'0信息维护'!$U$31)+IF('0信息维护'!$I$124=0,0,H18/('0信息维护'!$I$124)*'0信息维护'!$E$41*'0信息维护'!$T$31)+IF('0信息维护'!$I$125=0,0,I18/'0信息维护'!$I$125*'0信息维护'!$I$41) -> 0
A19: 3 | B19: =OFFSET('1课程考核方式及成绩组成'!$D$10,(ROW(B19)-5)/7,) -> 180301010 | C19: =OFFSET('1课程考核方式及成绩组成'!$E$10,(ROW(C19)-5)/7,) -> 童祉昂 | D19: ='0信息维护'!A$25 -> 课程目标1 | E19: =OFFSET('1课程考核方式及成绩组成'!$F$10,(ROW(E19)-5)/7,MOD((ROW(E19)-5),7)) -> 40 | F19: =OFFSET('1课程考核方式及成绩组成'!$N$10,(ROW(F19)-5)/7,MOD((ROW(F19)-5),7)) -> 0 | G19: =OFFSET('1课程考核方式及成绩组成'!$V$10,(ROW(G19)-5)/7,MOD((ROW(G19)-5),7)) -> 0 | H19: =OFFSET('1课程考核方式及成绩组成'!$AD$10,(ROW(H19)-5)/7,MOD((ROW(H19)-5),7)) -> 0 | I19: =OFFSET('1课程考核方式及成绩组成'!$AL$10,(ROW(I19)-5)/7,MOD((ROW(I19)-5),7)) -> 34 | J19: =IF('0信息维护'!$I$85=0,0,E19/('0信息维护'!$I$85)*'0信息维护'!$E$35*'0信息维护'!$S$25)+IF('0信息维护'!$I$86=0,0,F19/('0信息维护'!$I$86)*'0信息维护'!$E$35*'0信息维护'!$T$25)+IF('0信息维护'!$I$87=0,0,G19/('0信息维护'!$I$87)*'0信息维护'!$E$35*'0信息维护'!$U$25)+IF('0信息维护'!$I$88=0,0,H19/('0信息维护'!$I$88)*'0信息维护'!$E$35*'0信息维护'!$V$25)+IF('0信息维护'!$I$89=0,0,I19/'0信息维护'!$I$89*'0信息维护'!$I$35) -> 0.97222222 | K19: =J19*'0信息维护'!$D$132+J20*'0信息维护'!$D$133+J21*'0信息维护'!$D$134+J22*'0信息维护'!$D$135+J23*'0信息维护'!$D$136+J24*'0信息维护'!$D$137+J25*'0信息维护'!$D$138 -> 0.74053922
D20: ='0信息维护'!A$26 -> 课程目标2 | E20: =OFFSET('1课程考核方式及成绩组成'!$F$10,(ROW(E20)-5)/7,MOD((ROW(E20)-5),7)) -> 60 | F20: =OFFSET('1课程考核方式及成绩组成'!$N$10,(ROW(F20)-5)/7,MOD((ROW(F20)-5),7)) -> 0 | G20: =OFFSET('1课程考核方式及成绩组成'!$V$10,(ROW(G20)-5)/7,MOD((ROW(G20)-5),7)) -> 0 | H20: =OFFSET('1课程考核方式及成绩组成'!$AD$10,(ROW(H20)-5)/7,MOD((ROW(H20)-5),7)) -> 0 | I20: =OFFSET('1课程考核方式及成绩组成'!$AL$10,(ROW(I20)-5)/7,MOD((ROW(I20)-5),7)) -> 25 | J20: =IF('0信息维护'!$I$91=0,0,E20/('0信息维护'!$I$91)*'0信息维护'!$S$26*'0信息维护'!$E$36)+IF('0信息维护'!$I$92=0,0,F20/('0信息维护'!$I$92)*'0信息维护'!$T$26*'0信息维护'!$E$36)+IF('0信息维护'!$I$93=0,0,G20/('0信息维护'!$I$93)*'0信息维护'!$U$26*'0信息维护'!$E$36)+IF('0信息维护'!$I$94=0,0,H20/('0信息维护'!$I$94)*'0信息维护'!$V$26*'0信息维护'!$E$36)+IF('0信息维护'!$I$95=0,0,I20/'0信息维护'!$I$95*'0信息维护'!$I$36) -> 0.91666667
D21: ='0信息维护'!A$27 -> 课程目标3 | E21: =OFFSET('1课程考核方式及成绩组成'!$F$10,(ROW(E21)-5)/7,MOD((ROW(E21)-5),7)) -> 0 | F21: =OFFSET('1课程考核方式及成绩组成'!$N$10,(ROW(F21)-5)/7,MOD((ROW(F21)-5),7)) -> 0 | G21: =OFFSET('1课程考核方式及成绩组成'!$V$10,(ROW(G21)-5)/7,MOD((ROW(G21)-5),7)) -> 0 | H21: =OFFSET('1课程考核方式及成绩组成'!$AD$10,(ROW(H21)-5)/7,MOD((ROW(H21)-5),7)) -> 0 | I21: =OFFSET('1课程考核方式及成绩组成'!$AL$10,(ROW(I21)-5)/7,MOD((ROW(I21)-5),7)) -> 19 | J21: =IF('0信息维护'!$I$97=0,0,E21/('0信息维护'!$I$97)*'0信息维护'!$E$37*'0信息维护'!$S$27)+IF('0信息维护'!$I$98=0,0,F21/('0信息维护'!$I$98)*'0信息维护'!$E$37*'0信息维护'!$T$27)+IF('0信息维护'!$I$99=0,0,G21/('0信息维护'!$I$99)*'0信息维护'!$E$37*'0信息维护'!$U$27)+IF('0信息维护'!$I$100=0,0,H21/('0信息维护'!$I$100)*'0信息维护'!$E$37*'0信息维护'!$V$27)+IF('0信息维护'!$I$101=0,0,I21/'0信息维护'!$I$101*'0信息维护'!$I$37) -> 0.55882353
D22: ='0信息维护'!A$28 -> 课程目标4 | E22: =OFFSET('1课程考核方式及成绩组成'!$F$10,(ROW(E22)-5)/7,MOD((ROW(E22)-5),7)) -> 0 | F22: =OFFSET('1课程考核方式及成绩组成'!$N$10,(ROW(F22)-5)/7,MOD((ROW(F22)-5),7)) -> 60 | G22: =OFFSET('1课程考核方式及成绩组成'!$V$10,(ROW(G22)-5)/7,MOD((ROW(G22)-5),7)) -> 0 | H22: =OFFSET('1课程考核方式及成绩组成'!$AD$10,(ROW(H22)-5)/7,MOD((ROW(H22)-5),7)) -> 0 | I22: =OFFSET('1课程考核方式及成绩组成'!$AL$10,(ROW(I22)-5)/7,MOD((ROW(I22)-5),7)) -> 0 | J22: =IF('0信息维护'!$I$103=0,0,E22/('0信息维护'!$I$103)*'0信息维护'!$E$38*'0信息维护'!$S$28)+IF('0信息维护'!$I$104=0,0,F22/('0信息维护'!$I$104)*'0信息维护'!$E$38*'0信息维护'!$T$28)+IF('0信息维护'!$I$105=0,0,G22/('0信息维护'!$I$105)*'0信息维护'!$E$38*'0信息维护'!$U$28)+IF('0信息维护'!$I$106=0,0,H22/('0信息维护'!$I$106)*'0信息维护'!$E$38*'0信息维护'!$V$28)+IF('0信息维护'!$I$107=0,0,I22/'0信息维护'!$I$107*'0信息维护'!$I$38) -> 0.6
D23: ='0信息维护'!A$29 -> 课程目标5 | E23: =OFFSET('1课程考核方式及成绩组成'!$F$10,(ROW(E23)-5)/7,MOD((ROW(E23)-5),7)) -> 0 | F23: =OFFSET('1课程考核方式及成绩组成'!$N$10,(ROW(F23)-5)/7,MOD((ROW(F23)-5),7)) -> 0 | G23: =OFFSET('1课程考核方式及成绩组成'!$V$10,(ROW(G23)-5)/7,MOD((ROW(G23)-5),7)) -> 0 | H23: =OFFSET('1课程考核方式及成绩组成'!$AD$10,(ROW(H23)-5)/7,MOD((ROW(H23)-5),7)) -> 0 | I23: =OFFSET('1课程考核方式及成绩组成'!$AL$10,(ROW(I23)-5)/7,MOD((ROW(I23)-5),7)) -> 0 | J23: =IF('0信息维护'!$I$109=0,0,E23/('0信息维护'!$I$109)*'0信息维护'!$E$39*'0信息维护'!$S$29)+IF('0信息维护'!$I$110=0,0,F23/('0信息维护'!$I$110)*'0信息维护'!$E$39*'0信息维护'!$T$29)+IF('0信息维护'!$I$111=0,0,G23/('0信息维护'!$I$111)*'0信息维护'!$E$39*'0信息维护'!$U$29)+IF('0信息维护'!$I$112=0,0,H23/('0信息维护'!$I$112)*'0信息维护'!$E$39*'0信息维护'!$V$29)+IF('0信息维护'!$I$113=0,0,I23/'0信息维护'!$I$113*'0信息维护'!$I$39) -> 0
D24: ='0信息维护'!A$30 -> 课程目标6 | E24: =OFFSET('1课程考核方式及成绩组成'!$F$10,(ROW(E24)-5)/7,MOD((ROW(E24)-5),7)) -> 0 | F24: =OFFSET('1课程考核方式及成绩组成'!$N$10,(ROW(F24)-5)/7,MOD((ROW(F24)-5),7)) -> 0 | G24: =OFFSET('1课程考核方式及成绩组成'!$V$10,(ROW(G24)-5)/7,MOD((ROW(G24)-5),7)) -> 0 | H24: =OFFSET('1课程考核方式及成绩组成'!$AD$10,(ROW(H24)-5)/7,MOD((ROW(H24)-5),7)) -> 0 | I24: =OFFSET('1课程考核方式及成绩组成'!$AL$10,(ROW(I24)-5)/7,MOD((ROW(I24)-5),7)) -> 0 | J24: =IF('0信息维护'!$I$115=0,0,E24/('0信息维护'!$I$115)*'0信息维护'!$E$40*'0信息维护'!$S$30)+IF('0信息维护'!$I$116=0,0,F24/('0信息维护'!$I$116)*'0信息维护'!$E$40*'0信息维护'!$T$30)+IF('0信息维护'!$I$117=0,0,G24/('0信息维护'!$I$117)*'0信息维护'!$E$40*'0信息维护'!$U$30)+IF('0信息维护'!$I$118=0,0,H24/('0信息维护'!$I$118)*'0信息维护'!$E$40*'0信息维护'!$V$30)+IF('0信息维护'!$I$119=0,0,I24/'0信息维护'!$I$119*'0信息维护'!$I$40) -> 0
D25: ='0信息维护'!A$31 -> 课程目标7 | E25: =OFFSET('1课程考核方式及成绩组成'!$F$10,(ROW(E25)-5)/7,MOD((ROW(E25)-5),7)) -> 0 | F25: =OFFSET('1课程考核方式及成绩组成'!$N$10,(ROW(F25)-5)/7,MOD((ROW(F25)-5),7)) -> 0 | G25: =OFFSET('1课程考核方式及成绩组成'!$V$10,(ROW(G25)-5)/7,MOD((ROW(G25)-5),7)) -> 0 | H25: =OFFSET('1课程考核方式及成绩组成'!$AD$10,(ROW(H25)-5)/7,MOD((ROW(H25)-5),7)) -> 0 | I25: =OFFSET('1课程考核方式及成绩组成'!$AL$10,(ROW(I25)-5)/7,MOD((ROW(I25)-5),7)) -> 0 | J25: =IF('0信息维护'!$I$121=0,0,E25/('0信息维护'!$I$121)*'0信息维护'!$E$41*'0信息维护'!$S$31)+IF('0信息维护'!$I$122=0,0,F25/('0信息维护'!$I$122)*'0信息维护'!$E$41*'0信息维护'!$T$31)+IF('0信息维护'!$I$123=0,0,G25/('0信息维护'!$I$123)*'0信息维护'!$E$41*'0信息维护'!$U$31)+IF('0信息维护'!$I$124=0,0,H25/('0信息维护'!$I$124)*'0信息维护'!$E$41*'0信息维护'!$T$31)+IF('0信息维护'!$I$125=0,0,I25/'0信息维护'!$I$125*'0信息维护'!$I$41) -> 0
A26: 4 | B26: =OFFSET('1课程考核方式及成绩组成'!$D$10,(ROW(B26)-5)/7,) -> 180301042 | C26: =OFFSET('1课程考核方式及成绩组成'!$E$10,(ROW(C26)-5)/7,) -> 覃朝雄 | D26: ='0信息维护'!A$25 -> 课程目标1 | E26: =OFFSET('1课程考核方式及成绩组成'!$F$10,(ROW(E26)-5)/7,MOD((ROW(E26)-5),7)) -> 40 | F26: =OFFSET('1课程考核方式及成绩组成'!$N$10,(ROW(F26)-5)/7,MOD((ROW(F26)-5),7)) -> 0 | G26: =OFFSET('1课程考核方式及成绩组成'!$V$10,(ROW(G26)-5)/7,MOD((ROW(G26)-5),7)) -> 0 | H26: =OFFSET('1课程考核方式及成绩组成'!$AD$10,(ROW(H26)-5)/7,MOD((ROW(H26)-5),7)) -> 0 | I26: =OFFSET('1课程考核方式及成绩组成'!$AL$10,(ROW(I26)-5)/7,MOD((ROW(I26)-5),7)) -> 34 | J26: =IF('0信息维护'!$I$85=0,0,E26/('0信息维护'!$I$85)*'0信息维护'!$E$35*'0信息维护'!$S$25)+IF('0信息维护'!$I$86=0,0,F26/('0信息维护'!$I$86)*'0信息维护'!$E$35*'0信息维护'!$T$25)+IF('0信息维护'!$I$87=0,0,G26/('0信息维护'!$I$87)*'0信息维护'!$E$35*'0信息维护'!$U$25)+IF('0信息维护'!$I$88=0,0,H26/('0信息维护'!$I$88)*'0信息维护'!$E$35*'0信息维护'!$V$25)+IF('0信息维护'!$I$89=0,0,I26/'0信息维护'!$I$89*'0信息维护'!$I$35) -> 0.97222222 | K26: =J26*'0信息维护'!$D$132+J27*'0信息维护'!$D$133+J28*'0信息维护'!$D$134+J29*'0信息维护'!$D$135+J30*'0信息维护'!$D$136+J31*'0信息维护'!$D$137+J32*'0信息维护'!$D$138 -> 0.77289216
D27: ='0信息维护'!A$26 -> 课程目标2 | E27: =OFFSET('1课程考核方式及成绩组成'!$F$10,(ROW(E27)-5)/7,MOD((ROW(E27)-5),7)) -> 60 | F27: =OFFSET('1课程考核方式及成绩组成'!$N$10,(ROW(F27)-5)/7,MOD((ROW(F27)-5),7)) -> 0 | G27: =OFFSET('1课程考核方式及成绩组成'!$V$10,(ROW(G27)-5)/7,MOD((ROW(G27)-5),7)) -> 0 | H27: =OFFSET('1课程考核方式及成绩组成'!$AD$10,(ROW(H27)-5)/7,MOD((ROW(H27)-5),7)) -> 0 | I27: =OFFSET('1课程考核方式及成绩组成'!$AL$10,(ROW(I27)-5)/7,MOD((ROW(I27)-5),7)) -> 21 | J27: =IF('0信息维护'!$I$91=0,0,E27/('0信息维护'!$I$91)*'0信息维护'!$S$26*'0信息维护'!$E$36)+IF('0信息维护'!$I$92=0,0,F27/('0信息维护'!$I$92)*'0信息维护'!$T$26*'0信息维护'!$E$36)+IF('0信息维护'!$I$93=0,0,G27/('0信息维护'!$I$93)*'0信息维护'!$U$26*'0信息维护'!$E$36)+IF('0信息维护'!$I$94=0,0,H27/('0信息维护'!$I$94)*'0信息维护'!$V$26*'0信息维护'!$E$36)+IF('0信息维护'!$I$95=0,0,I27/'0信息维护'!$I$95*'0信息维护'!$I$36) -> 0.85
D28: ='0信息维护'!A$27 -> 课程目标3 | E28: =OFFSET('1课程考核方式及成绩组成'!$F$10,(ROW(E28)-5)/7,MOD((ROW(E28)-5),7)) -> 0 | F28: =OFFSET('1课程考核方式及成绩组成'!$N$10,(ROW(F28)-5)/7,MOD((ROW(F28)-5),7)) -> 0 | G28: =OFFSET('1课程考核方式及成绩组成'!$V$10,(ROW(G28)-5)/7,MOD((ROW(G28)-5),7)) -> 0 | H28: =OFFSET('1课程考核方式及成绩组成'!$AD$10,(ROW(H28)-5)/7,MOD((ROW(H28)-5),7)) -> 0 | I28: =OFFSET('1课程考核方式及成绩组成'!$AL$10,(ROW(I28)-5)/7,MOD((ROW(I28)-5),7)) -> 20 | J28: =IF('0信息维护'!$I$97=0,0,E28/('0信息维护'!$I$97)*'0信息维护'!$E$37*'0信息维护'!$S$27)+IF('0信息维护'!$I$98=0,0,F28/('0信息维护'!$I$98)*'0信息维护'!$E$37*'0信息维护'!$T$27)+IF('0信息维护'!$I$99=0,0,G28/('0信息维护'!$I$99)*'0信息维护'!$E$37*'0信息维护'!$U$27)+IF('0信息维护'!$I$100=0,0,H28/('0信息维护'!$I$100)*'0信息维护'!$E$37*'0信息维护'!$V$27)+IF('0信息维护'!$I$101=0,0,I28/'0信息维护'!$I$101*'0信息维护'!$I$37) -> 0.58823529
D29: ='0信息维护'!A$28 -> 课程目标4 | E29: =OFFSET('1课程考核方式及成绩组成'!$F$10,(ROW(E29)-5)/7,MOD((ROW(E29)-5),7)) -> 0 | F29: =OFFSET('1课程考核方式及成绩组成'!$N$10,(ROW(F29)-5)/7,MOD((ROW(F29)-5),7)) -> 75 | G29: =OFFSET('1课程考核方式及成绩组成'!$V$10,(ROW(G29)-5)/7,MOD((ROW(G29)-5),7)) -> 0 | H29: =OFFSET('1课程考核方式及成绩组成'!$AD$10,(ROW(H29)-5)/7,MOD((ROW(H29)-5),7)) -> 0 | I29: =OFFSET('1课程考核方式及成绩组成'!$AL$10,(ROW(I29)-5)/7,MOD((ROW(I29)-5),7)) -> 0 | J29: =IF('0信息维护'!$I$103=0,0,E29/('0信息维护'!$I$103)*'0信息维护'!$E$38*'0信息维护'!$S$28)+IF('0信息维护'!$I$104=0,0,F29/('0信息维护'!$I$104)*'0信息维护'!$E$38*'0信息维护'!$T$28)+IF('0信息维护'!$I$105=0,0,G29/('0信息维护'!$I$105)*'0信息维护'!$E$38*'0信息维护'!$U$28)+IF('0信息维护'!$I$106=0,0,H29/('0信息维护'!$I$106)*'0信息维护'!$E$38*'0信息维护'!$V$28)+IF('0信息维护'!$I$107=0,0,I29/'0信息维护'!$I$107*'0信息维护'!$I$38) -> 0.75
D30: ='0信息维护'!A$29 -> 课程目标5 | E30: =OFFSET('1课程考核方式及成绩组成'!$F$10,(ROW(E30)-5)/7,MOD((ROW(E30)-5),7)) -> 0 | F30: =OFFSET('1课程考核方式及成绩组成'!$N$10,(ROW(F30)-5)/7,MOD((ROW(F30)-5),7)) -> 0 | G30: =OFFSET('1课程考核方式及成绩组成'!$V$10,(ROW(G30)-5)/7,MOD((ROW(G30)-5),7)) -> 0 | H30: =OFFSET('1课程考核方式及成绩组成'!$AD$10,(ROW(H30)-5)/7,MOD((ROW(H30)-5),7)) -> 0 | I30: =OFFSET('1课程考核方式及成绩组成'!$AL$10,(ROW(I30)-5)/7,MOD((ROW(I30)-5),7)) -> 0 | J30: =IF('0信息维护'!$I$109=0,0,E30/('0信息维护'!$I$109)*'0信息维护'!$E$39*'0信息维护'!$S$29)+IF('0信息维护'!$I$110=0,0,F30/('0信息维护'!$I$110)*'0信息维护'!$E$39*'0信息维护'!$T$29)+IF('0信息维护'!$I$111=0,0,G30/('0信息维护'!$I$111)*'0信息维护'!$E$39*'0信息维护'!$U$29)+IF('0信息维护'!$I$112=0,0,H30/('0信息维护'!$I$112)*'0信息维护'!$E$39*'0信息维护'!$V$29)+IF('0信息维护'!$I$113=0,0,I30/'0信息维护'!$I$113*'0信息维护'!$I$39) -> 0
D31: ='0信息维护'!A$30 -> 课程目标6 | E31: =OFFSET('1课程考核方式及成绩组成'!$F$10,(ROW(E31)-5)/7,MOD((ROW(E31)-5),7)) -> 0 | F31: =OFFSET('1课程考核方式及成绩组成'!$N$10,(ROW(F31)-5)/7,MOD((ROW(F31)-5),7)) -> 0 | G31: =OFFSET('1课程考核方式及成绩组成'!$V$10,(ROW(G31)-5)/7,MOD((ROW(G31)-5),7)) -> 0 | H31: =OFFSET('1课程考核方式及成绩组成'!$AD$10,(ROW(H31)-5)/7,MOD((ROW(H31)-5),7)) -> 0 | I31: =OFFSET('1课程考核方式及成绩组成'!$AL$10,(ROW(I31)-5)/7,MOD((ROW(I31)-5),7)) -> 0 | J31: =IF('0信息维护'!$I$115=0,0,E31/('0信息维护'!$I$115)*'0信息维护'!$E$40*'0信息维护'!$S$30)+IF('0信息维护'!$I$116=0,0,F31/('0信息维护'!$I$116)*'0信息维护'!$E$40*'0信息维护'!$T$30)+IF('0信息维护'!$I$117=0,0,G31/('0信息维护'!$I$117)*'0信息维护'!$E$40*'0信息维护'!$U$30)+IF('0信息维护'!$I$118=0,0,H31/('0信息维护'!$I$118)*'0信息维护'!$E$40*'0信息维护'!$V$30)+IF('0信息维护'!$I$119=0,0,I31/'0信息维护'!$I$119*'0信息维护'!$I$40) -> 0
D32: ='0信息维护'!A$31 -> 课程目标7 | E32: =OFFSET('1课程考核方式及成绩组成'!$F$10,(ROW(E32)-5)/7,MOD((ROW(E32)-5),7)) -> 0 | F32: =OFFSET('1课程考核方式及成绩组成'!$N$10,(ROW(F32)-5)/7,MOD((ROW(F32)-5),7)) -> 0 | G32: =OFFSET('1课程考核方式及成绩组成'!$V$10,(ROW(G32)-5)/7,MOD((ROW(G32)-5),7)) -> 0 | H32: =OFFSET('1课程考核方式及成绩组成'!$AD$10,(ROW(H32)-5)/7,MOD((ROW(H32)-5),7)) -> 0 | I32: =OFFSET('1课程考核方式及成绩组成'!$AL$10,(ROW(I32)-5)/7,MOD((ROW(I32)-5),7)) -> 0 | J32: =IF('0信息维护'!$I$121=0,0,E32/('0信息维护'!$I$121)*'0信息维护'!$E$41*'0信息维护'!$S$31)+IF('0信息维护'!$I$122=0,0,F32/('0信息维护'!$I$122)*'0信息维护'!$E$41*'0信息维护'!$T$31)+IF('0信息维护'!$I$123=0,0,G32/('0信息维护'!$I$123)*'0信息维护'!$E$41*'0信息维护'!$U$31)+IF('0信息维护'!$I$124=0,0,H32/('0信息维护'!$I$124)*'0信息维护'!$E$41*'0信息维护'!$T$31)+IF('0信息维护'!$I$125=0,0,I32/'0信息维护'!$I$125*'0信息维护'!$I$41) -> 0
A33: 5 | B33: =OFFSET('1课程考核方式及成绩组成'!$D$10,(ROW(B33)-5)/7,) -> 190301001 | C33: =OFFSET('1课程考核方式及成绩组成'!$E$10,(ROW(C33)-5)/7,) -> 温佳洛 | D33: ='0信息维护'!A$25 -> 课程目标1 | E33: =OFFSET('1课程考核方式及成绩组成'!$F$10,(ROW(E33)-5)/7,MOD((ROW(E33)-5),7)) -> 35 | F33: =OFFSET('1课程考核方式及成绩组成'!$N$10,(ROW(F33)-5)/7,MOD((ROW(F33)-5),7)) -> 0 | G33: =OFFSET('1课程考核方式及成绩组成'!$V$10,(ROW(G33)-5)/7,MOD((ROW(G33)-5),7)) -> 0 | H33: =OFFSET('1课程考核方式及成绩组成'!$AD$10,(ROW(H33)-5)/7,MOD((ROW(H33)-5),7)) -> 0 | I33: =OFFSET('1课程考核方式及成绩组成'!$AL$10,(ROW(I33)-5)/7,MOD((ROW(I33)-5),7)) -> 22 | J33: =IF('0信息维护'!$I$85=0,0,E33/('0信息维护'!$I$85)*'0信息维护'!$E$35*'0信息维护'!$S$25)+IF('0信息维护'!$I$86=0,0,F33/('0信息维护'!$I$86)*'0信息维护'!$E$35*'0信息维护'!$T$25)+IF('0信息维护'!$I$87=0,0,G33/('0信息维护'!$I$87)*'0信息维护'!$E$35*'0信息维护'!$U$25)+IF('0信息维护'!$I$88=0,0,H33/('0信息维护'!$I$88)*'0信息维护'!$E$35*'0信息维护'!$V$25)+IF('0信息维护'!$I$89=0,0,I33/'0信息维护'!$I$89*'0信息维护'!$I$35) -> 0.74305556 | K33: =J33*'0信息维护'!$D$132+J34*'0信息维护'!$D$133+J35*'0信息维护'!$D$134+J36*'0信息维护'!$D$135+J37*'0信息维护'!$D$136+J38*'0信息维护'!$D$137+J39*'0信息维护'!$D$138 -> 0.63995833
D34: ='0信息维护'!A$26 -> 课程目标2 | E34: =OFFSET('1课程考核方式及成绩组成'!$F$10,(ROW(E34)-5)/7,MOD((ROW(E34)-5),7)) -> 55 | F34: =OFFSET('1课程考核方式及成绩组成'!$N$10,(ROW(F34)-5)/7,MOD((ROW(F34)-5),7)) -> 0 | G34: =OFFSET('1课程考核方式及成绩组成'!$V$10,(ROW(G34)-5)/7,MOD((ROW(G34)-5),7)) -> 0 | H34: =OFFSET('1课程考核方式及成绩组成'!$AD$10,(ROW(H34)-5)/7,MOD((ROW(H34)-5),7)) -> 0 | I34: =OFFSET('1课程考核方式及成绩组成'!$AL$10,(ROW(I34)-5)/7,MOD((ROW(I34)-5),7)) -> 7 | J34: =IF('0信息维护'!$I$91=0,0,E34/('0信息维护'!$I$91)*'0信息维护'!$S$26*'0信息维护'!$E$36)+IF('0信息维护'!$I$92=0,0,F34/('0信息维护'!$I$92)*'0信息维护'!$T$26*'0信息维护'!$E$36)+IF('0信息维护'!$I$93=0,0,G34/('0信息维护'!$I$93)*'0信息维护'!$U$26*'0信息维护'!$E$36)+IF('0信息维护'!$I$94=0,0,H34/('0信息维护'!$I$94)*'0信息维护'!$V$26*'0信息维护'!$E$36)+IF('0信息维护'!$I$95=0,0,I34/'0信息维护'!$I$95*'0信息维护'!$I$36) -> 0.575
D35: ='0信息维护'!A$27 -> 课程目标3 | E35: =OFFSET('1课程考核方式及成绩组成'!$F$10,(ROW(E35)-5)/7,MOD((ROW(E35)-5),7)) -> 0 | F35: =OFFSET('1课程考核方式及成绩组成'!$N$10,(ROW(F35)-5)/7,MOD((ROW(F35)-5),7)) -> 0 | G35: =OFFSET('1课程考核方式及成绩组成'!$V$10,(ROW(G35)-5)/7,MOD((ROW(G35)-5),7)) -> 0 | H35: =OFFSET('1课程考核方式及成绩组成'!$AD$10,(ROW(H35)-5)/7,MOD((ROW(H35)-5),7)) -> 0 | I35: =OFFSET('1课程考核方式及成绩组成'!$AL$10,(ROW(I35)-5)/7,MOD((ROW(I35)-5),7)) -> 17 | J35: =IF('0信息维护'!$I$97=0,0,E35/('0信息维护'!$I$97)*'0信息维护'!$E$37*'0信息维护'!$S$27)+IF('0信息维护'!$I$98=0,0,F35/('0信息维护'!$I$98)*'0信息维护'!$E$37*'0信息维护'!$T$27)+IF('0信息维护'!$I$99=0,0,G35/('0信息维护'!$I$99)*'0信息维护'!$E$37*'0信息维护'!$U$27)+IF('0信息维护'!$I$100=0,0,H35/('0信息维护'!$I$100)*'0信息维护'!$E$37*'0信息维护'!$V$27)+IF('0信息维护'!$I$101=0,0,I35/'0信息维护'!$I$101*'0信息维护'!$I$37) -> 0.5
D36: ='0信息维护'!A$28 -> 课程目标4 | E36: =OFFSET('1课程考核方式及成绩组成'!$F$10,(ROW(E36)-5)/7,MOD((ROW(E36)-5),7)) -> 0 | F36: =OFFSET('1课程考核方式及成绩组成'!$N$10,(ROW(F36)-5)/7,MOD((ROW(F36)-5),7)) -> 77 | G36: =OFFSET('1课程考核方式及成绩组成'!$V$10,(ROW(G36)-5)/7,MOD((ROW(G36)-5),7)) -> 0 | H36: =OFFSET('1课程考核方式及成绩组成'!$AD$10,(ROW(H36)-5)/7,MOD((ROW(H36)-5),7)) -> 0 | I36: =OFFSET('1课程考核方式及成绩组成'!$AL$10,(ROW(I36)-5)/7,MOD((ROW(I36)-5),7)) -> 0 | J36: =IF('0信息维护'!$I$103=0,0,E36/('0信息维护'!$I$103)*'0信息维护'!$E$38*'0信息维护'!$S$28)+IF('0信息维护'!$I$104=0,0,F36/('0信息维护'!$I$104)*'0信息维护'!$E$38*'0信息维护'!$T$28)+IF('0信息维护'!$I$105=0,0,G36/('0信息维护'!$I$105)*'0信息维护'!$E$38*'0信息维护'!$U$28)+IF('0信息维护'!$I$106=0,0,H36/('0信息维护'!$I$106)*'0信息维护'!$E$38*'0信息维护'!$V$28)+IF('0信息维护'!$I$107=0,0,I36/'0信息维护'!$I$107*'0信息维护'!$I$38) -> 0.77
D37: ='0信息维护'!A$29 -> 课程目标5 | E37: =OFFSET('1课程考核方式及成绩组成'!$F$10,(ROW(E37)-5)/7,MOD((ROW(E37)-5),7)) -> 0 | F37: =OFFSET('1课程考核方式及成绩组成'!$N$10,(ROW(F37)-5)/7,MOD((ROW(F37)-5),7)) -> 0 | G37: =OFFSET('1课程考核方式及成绩组成'!$V$10,(ROW(G37)-5)/7,MOD((ROW(G37)-5),7)) -> 0 | H37: =OFFSET('1课程考核方式及成绩组成'!$AD$10,(ROW(H37)-5)/7,MOD((ROW(H37)-5),7)) -> 0 | I37: =OFFSET('1课程考核方式及成绩组成'!$AL$10,(ROW(I37)-5)/7,MOD((ROW(I37)-5),7)) -> 0 | J37: =IF('0信息维护'!$I$109=0,0,E37/('0信息维护'!$I$109)*'0信息维护'!$E$39*'0信息维护'!$S$29)+IF('0信息维护'!$I$110=0,0,F37/('0信息维护'!$I$110)*'0信息维护'!$E$39*'0信息维护'!$T$29)+IF('0信息维护'!$I$111=0,0,G37/('0信息维护'!$I$111)*'0信息维护'!$E$39*'0信息维护'!$U$29)+IF('0信息维护'!$I$112=0,0,H37/('0信息维护'!$I$112)*'0信息维护'!$E$39*'0信息维护'!$V$29)+IF('0信息维护'!$I$113=0,0,I37/'0信息维护'!$I$113*'0信息维护'!$I$39) -> 0
D38: ='0信息维护'!A$30 -> 课程目标6 | E38: =OFFSET('1课程考核方式及成绩组成'!$F$10,(ROW(E38)-5)/7,MOD((ROW(E38)-5),7)) -> 0 | F38: =OFFSET('1课程考核方式及成绩组成'!$N$10,(ROW(F38)-5)/7,MOD((ROW(F38)-5),7)) -> 0 | G38: =OFFSET('1课程考核方式及成绩组成'!$V$10,(ROW(G38)-5)/7,MOD((ROW(G38)-5),7)) -> 0 | H38: =OFFSET('1课程考核方式及成绩组成'!$AD$10,(ROW(H38)-5)/7,MOD((ROW(H38)-5),7)) -> 0 | I38: =OFFSET('1课程考核方式及成绩组成'!$AL$10,(ROW(I38)-5)/7,MOD((ROW(I38)-5),7)) -> 0 | J38: =IF('0信息维护'!$I$115=0,0,E38/('0信息维护'!$I$115)*'0信息维护'!$E$40*'0信息维护'!$S$30)+IF('0信息维护'!$I$116=0,0,F38/('0信息维护'!$I$116)*'0信息维护'!$E$40*'0信息维护'!$T$30)+IF('0信息维护'!$I$117=0,0,G38/('0信息维护'!$I$117)*'0信息维护'!$E$40*'0信息维护'!$U$30)+IF('0信息维护'!$I$118=0,0,H38/('0信息维护'!$I$118)*'0信息维护'!$E$40*'0信息维护'!$V$30)+IF('0信息维护'!$I$119=0,0,I38/'0信息维护'!$I$119*'0信息维护'!$I$40) -> 0
D39: ='0信息维护'!A$31 -> 课程目标7 | E39: =OFFSET('1课程考核方式及成绩组成'!$F$10,(ROW(E39)-5)/7,MOD((ROW(E39)-5),7)) -> 0 | F39: =OFFSET('1课程考核方式及成绩组成'!$N$10,(ROW(F39)-5)/7,MOD((ROW(F39)-5),7)) -> 0 | G39: =OFFSET('1课程考核方式及成绩组成'!$V$10,(ROW(G39)-5)/7,MOD((ROW(G39)-5),7)) -> 0 | H39: =OFFSET('1课程考核方式及成绩组成'!$AD$10,(ROW(H39)-5)/7,MOD((ROW(H39)-5),7)) -> 0 | I39: =OFFSET('1课程考核方式及成绩组成'!$AL$10,(ROW(I39)-5)/7,MOD((ROW(I39)-5),7)) -> 0 | J39: =IF('0信息维护'!$I$121=0,0,E39/('0信息维护'!$I$121)*'0信息维护'!$E$41*'0信息维护'!$S$31)+IF('0信息维护'!$I$122=0,0,F39/('0信息维护'!$I$122)*'0信息维护'!$E$41*'0信息维护'!$T$31)+IF('0信息维护'!$I$123=0,0,G39/('0信息维护'!$I$123)*'0信息维护'!$E$41*'0信息维护'!$U$31)+IF('0信息维护'!$I$124=0,0,H39/('0信息维护'!$I$124)*'0信息维护'!$E$41*'0信息维护'!$T$31)+IF('0信息维护'!$I$125=0,0,I39/'0信息维护'!$I$125*'0信息维护'!$I$41) -> 0
A40: 6 | B40: =OFFSET('1课程考核方式及成绩组成'!$D$10,(ROW(B40)-5)/7,) -> 190301002 | C40: =OFFSET('1课程考核方式及成绩组成'!$E$10,(ROW(C40)-5)/7,) -> 周涛 | D40: ='0信息维护'!A$25 -> 课程目标1 | E40: =OFFSET('1课程考核方式及成绩组成'!$F$10,(ROW(E40)-5)/7,MOD((ROW(E40)-5),7)) -> 40 | F40: =OFFSET('1课程考核方式及成绩组成'!$N$10,(ROW(F40)-5)/7,MOD((ROW(F40)-5),7)) -> 0 | G40: =OFFSET('1课程考核方式及成绩组成'!$V$10,(ROW(G40)-5)/7,MOD((ROW(G40)-5),7)) -> 0 | H40: =OFFSET('1课程考核方式及成绩组成'!$AD$10,(ROW(H40)-5)/7,MOD((ROW(H40)-5),7)) -> 0 | I40: =OFFSET('1课程考核方式及成绩组成'!$AL$10,(ROW(I40)-5)/7,MOD((ROW(I40)-5),7)) -> 32 | J40: =IF('0信息维护'!$I$85=0,0,E40/('0信息维护'!$I$85)*'0信息维护'!$E$35*'0信息维护'!$S$25)+IF('0信息维护'!$I$86=0,0,F40/('0信息维护'!$I$86)*'0信息维护'!$E$35*'0信息维护'!$T$25)+IF('0信息维护'!$I$87=0,0,G40/('0信息维护'!$I$87)*'0信息维护'!$E$35*'0信息维护'!$U$25)+IF('0信息维护'!$I$88=0,0,H40/('0信息维护'!$I$88)*'0信息维护'!$E$35*'0信息维护'!$V$25)+IF('0信息维护'!$I$89=0,0,I40/'0信息维护'!$I$89*'0信息维护'!$I$35) -> 0.94444444 | K40: =J40*'0信息维护'!$D$132+J41*'0信息维护'!$D$133+J42*'0信息维护'!$D$134+J43*'0信息维护'!$D$135+J44*'0信息维护'!$D$136+J45*'0信息维护'!$D$137+J46*'0信息维护'!$D$138 -> 0.8864902
D41: ='0信息维护'!A$26 -> 课程目标2 | E41: =OFFSET('1课程考核方式及成绩组成'!$F$10,(ROW(E41)-5)/7,MOD((ROW(E41)-5),7)) -> 60 | F41: =OFFSET('1课程考核方式及成绩组成'!$N$10,(ROW(F41)-5)/7,MOD((ROW(F41)-5),7)) -> 0 | G41: =OFFSET('1课程考核方式及成绩组成'!$V$10,(ROW(G41)-5)/7,MOD((ROW(G41)-5),7)) -> 0 | H41: =OFFSET('1课程考核方式及成绩组成'!$AD$10,(ROW(H41)-5)/7,MOD((ROW(H41)-5),7)) -> 0 | I41: =OFFSET('1课程考核方式及成绩组成'!$AL$10,(ROW(I41)-5)/7,MOD((ROW(I41)-5),7)) -> 30 | J41: =IF('0信息维护'!$I$91=0,0,E41/('0信息维护'!$I$91)*'0信息维护'!$S$26*'0信息维护'!$E$36)+IF('0信息维护'!$I$92=0,0,F41/('0信息维护'!$I$92)*'0信息维护'!$T$26*'0信息维护'!$E$36)+IF('0信息维护'!$I$93=0,0,G41/('0信息维护'!$I$93)*'0信息维护'!$U$26*'0信息维护'!$E$36)+IF('0信息维护'!$I$94=0,0,H41/('0信息维护'!$I$94)*'0信息维护'!$V$26*'0信息维护'!$E$36)+IF('0信息维护'!$I$95=0,0,I41/'0信息维护'!$I$95*'0信息维护'!$I$36) -> 1
...

Sheet 5绘图数据
A1: 序号 | B1: 学号 | C1: 平均达 成度 姓名 | D1: 目标1 | E1: 目标2 | F1: 目标3 | G1: 目标4 | H1: 目标5 | I1: 目标6 | J1: 目标7 | K1: 总目标 | M1: 目标1 | N1: 目标2 | O1: 目标3 | P1: 目标4 | Q1: 目标5 | R1: 目标6 | S1: 目标7 | T1: 总目标 | V1: 期望值
D2: =SUM(D3:D143)/'0信息维护'!$M$6 -> 0.82047872 | E2: =SUM(E3:E143)/'0信息维护'!$M$6 -> 0.77990544 | F2: =SUM(F3:F143)/'0信息维护'!$M$6 -> 0.5598665 | G2: =SUM(G3:G143)/'0信息维护'!$M$6 -> 0.78801418 | H2: =SUM(H3:H12)/'0信息维护'!$M$6 -> 0 | I2: =SUM(I3:I12)/'0信息维护'!$M$6 -> 0 | J2: =SUM(J3:J12)/'0信息维护'!$M$6 -> 0 | K2: =SUM(K3:K140)/'0信息维护'!$M$6 -> 0.71858731 | M2: 平均达成度
A3: 0 | B3: ='1课程考核方式及成绩组成'!D10 -> 180202041 | C3: ='1课程考核方式及成绩组成'!E10 -> 林振杨 | D3: =OFFSET('4学生课程目标达成度'!J$5,(ROW(D3)-3)*7,) -> 0.76388889 | E3: =OFFSET('4学生课程目标达成度'!J$6,(ROW(E3)-3)*7,) -> 0.75 | F3: =OFFSET('4学生课程目标达成度'!J$7,(ROW(F3)-3)*7,) -> 0.41176471 | G3: =OFFSET('4学生课程目标达成度'!J$8,(ROW(G3)-3)*7,) -> 0.73 | H3: =OFFSET('4学生课程目标达成度'!J$9,(ROW(H3)-3)*7,) -> 0 | I3: =OFFSET('4学生课程目标达成度'!J$10,(ROW(I3)-3)*7,) -> 0 | J3: =OFFSET('4学生课程目标达成度'!J$11,(ROW(J3)-3)*7,) -> 0 | K3: =OFFSET('4学生课程目标达成度'!K$5,(ROW(K3)-3)*7,) -> 0.66152451 | M3: =$D$2 -> 0.82047872 | N3: =$E$2 -> 0.77990544 | O3: =$F$2 -> 0.5598665 | P3: =$G$2 -> 0.78801418 | Q3: =$H$2 -> 0 | R3: =$I$2 -> 0 | S3: =$J$2 -> 0 | T3: =$K$2 -> 0.71858731 | V3: 0.65
A4: 1 | B4: ='1课程考核方式及成绩组成'!D11 -> 180301007 | C4: ='1课程考核方式及成绩组成'!E11 -> 刘彪 | D4: =OFFSET('4学生课程目标达成度'!J$5,(ROW(D4)-3)*7,) -> 0.91666667 | E4: =OFFSET('4学生课程目标达成度'!J$6,(ROW(E4)-3)*7,) -> 0.9 | F4: =OFFSET('4学生课程目标达成度'!J$7,(ROW(F4)-3)*7,) -> 0.55882353 | G4: =OFFSET('4学生课程目标达成度'!J$8,(ROW(G4)-3)*7,) -> 0.83 | H4: =OFFSET('4学生课程目标达成度'!J$9,(ROW(H4)-3)*7,) -> 0 | I4: =OFFSET('4学生课程目标达成度'!J$10,(ROW(I4)-3)*7,) -> 0 | J4: =OFFSET('4学生课程目标达成度'!J$11,(ROW(J4)-3)*7,) -> 0 | K4: =OFFSET('4学生课程目标达成度'!K$5,(ROW(K4)-3)*7,) -> 0.79620588 | M4: =$D$2 -> 0.82047872 | N4: =$E$2 -> 0.77990544 | O4: =$F$2 -> 0.5598665 | P4: =$G$2 -> 0.78801418 | Q4: =$H$2 -> 0 | R4: =$I$2 -> 0 | S4: =$J$2 -> 0 | T4: =$K$2 -> 0.71858731 | V4: 0.65 | X4: 课程目标1 | Y4: ='3课程达成度分析报告'!T51 -> 0.8464539 | Z4: 0.65
A5: 2 | B5: ='1课程考核方式及成绩组成'!D12 -> 180301010 | C5: ='1课程考核方式及成绩组成'!E12 -> 童祉昂 | D5: =OFFSET('4学生课程目标达成度'!J$5,(ROW(D5)-3)*7,) -> 0.97222222 | E5: =OFFSET('4学生课程目标达成度'!J$6,(ROW(E5)-3)*7,) -> 0.91666667 | F5: =OFFSET('4学生课程目标达成度'!J$7,(ROW(F5)-3)*7,) -> 0.55882353 | G5: =OFFSET('4学生课程目标达成度'!J$8,(ROW(G5)-3)*7,) -> 0.6 | H5: =OFFSET('4学生课程目标达成度'!J$9,(ROW(H5)-3)*7,) -> 0 | I5: =OFFSET('4学生课程目标达成度'!J$10,(ROW(I5)-3)*7,) -> 0 | J5: =OFFSET('4学生课程目标达成度'!J$11,(ROW(J5)-3)*7,) -> 0 | K5: =OFFSET('4学生课程目标达成度'!K$5,(ROW(K5)-3)*7,) -> 0.74053922 | M5: =$D$2 -> 0.82047872 | N5: =$E$2 -> 0.77990544 | O5: =$F$2 -> 0.5598665 | P5: =$G$2 -> 0.78801418 | Q5: =$H$2 -> 0 | R5: =$I$2 -> 0 | S5: =$J$2 -> 0 | T5: =$K$2 -> 0.71858731 | V5: 0.65 | X5: 课程目标2 | Y5: ='3课程达成度分析报告'!T57 -> 0.81711584 | Z5: 0.65
A6: 3 | B6: ='1课程考核方式及成绩组成'!D13 -> 180301042 | C6: ='1课程考核方式及成绩组成'!E13 -> 覃朝雄 | D6: =OFFSET('4学生课程目标达成度'!J$5,(ROW(D6)-3)*7,) -> 0.97222222 | E6: =OFFSET('4学生课程目标达成度'!J$6,(ROW(E6)-3)*7,) -> 0.85 | F6: =OFFSET('4学生课程目标达成度'!J$7,(ROW(F6)-3)*7,) -> 0.58823529 | G6: =OFFSET('4学生课程目标达成度'!J$8,(ROW(G6)-3)*7,) -> 0.75 | H6: =OFFSET('4学生课程目标达成度'!J$9,(ROW(H6)-3)*7,) -> 0 | I6: =OFFSET('4学生课程目标达成度'!J$10,(ROW(I6)-3)*7,) -> 0 | J6: =OFFSET('4学生课程目标达成度'!J$11,(ROW(J6)-3)*7,) -> 0 | K6: =OFFSET('4学生课程目标达成度'!K$5,(ROW(K6)-3)*7,) -> 0.77289216 | M6: =$D$2 -> 0.82047872 | N6: =$E$2 -> 0.77990544 | O6: =$F$2 -> 0.5598665 | P6: =$G$2 -> 0.78801418 | Q6: =$H$2 -> 0 | R6: =$I$2 -> 0 | S6: =$J$2 -> 0 | T6: =$K$2 -> 0.71858731 | V6: 0.65 | X6: 课程目标3 | Y6: ='3课程达成度分析报告'!T63 -> 0.63909887 | Z6: 0.65
A7: 4 | B7: ='1课程考核方式及成绩组成'!D14 -> 190301001 | C7: ='1课程考核方式及成绩组成'!E14 -> 温佳洛 | D7: =OFFSET('4学生课程目标达成度'!J$5,(ROW(D7)-3)*7,) -> 0.74305556 | E7: =OFFSET('4学生课程目标达成度'!J$6,(ROW(E7)-3)*7,) -> 0.575 | F7: =OFFSET('4学生课程目标达成度'!J$7,(ROW(F7)-3)*7,) -> 0.5 | G7: =OFFSET('4学生课程目标达成度'!J$8,(ROW(G7)-3)*7,) -> 0.77 | H7: =OFFSET('4学生课程目标达成度'!J$9,(ROW(H7)-3)*7,) -> 0 | I7: =OFFSET('4学生课程目标达成度'!J$10,(ROW(I7)-3)*7,) -> 0 | J7: =OFFSET('4学生课程目标达成度'!J$11,(ROW(J7)-3)*7,) -> 0 | K7: =OFFSET('4学生课程目标达成度'!K$5,(ROW(K7)-3)*7,) -> 0.63995833 | M7: =$D$2 -> 0.82047872 | N7: =$E$2 -> 0.77990544 | O7: =$F$2 -> 0.5598665 | P7: =$G$2 -> 0.78801418 | Q7: =$H$2 -> 0 | R7: =$I$2 -> 0 | S7: =$J$2 -> 0 | T7: =$K$2 -> 0.71858731 | V7: 0.65 | X7: 课程目标4 | Y7: ='3课程达成度分析报告'!T69 -> 0.82303546 | Z7: 0.65
A8: 5 | B8: ='1课程考核方式及成绩组成'!D15 -> 190301002 | C8: ='1课程考核方式及成绩组成'!E15 -> 周涛 | D8: =OFFSET('4学生课程目标达成度'!J$5,(ROW(D8)-3)*7,) -> 0.94444444 | E8: =OFFSET('4学生课程目标达成度'!J$6,(ROW(E8)-3)*7,) -> 1 | F8: =OFFSET('4学生课程目标达成度'!J$7,(ROW(F8)-3)*7,) -> 0.73529412 | G8: =OFFSET('4学生课程目标达成度'!J$8,(ROW(G8)-3)*7,) -> 0.87 | H8: =OFFSET('4学生课程目标达成度'!J$9,(ROW(H8)-3)*7,) -> 0 | I8: =OFFSET('4学生课程目标达成度'!J$10,(ROW(I8)-3)*7,) -> 0 | J8: =OFFSET('4学生课程目标达成度'!J$11,(ROW(J8)-3)*7,) -> 0 | K8: =OFFSET('4学生课程目标达成度'!K$5,(ROW(K8)-3)*7,) -> 0.8864902 | M8: =$D$2 -> 0.82047872 | N8: =$E$2 -> 0.77990544 | O8: =$F$2 -> 0.5598665 | P8: =$G$2 -> 0.78801418 | Q8: =$H$2 -> 0 | R8: =$I$2 -> 0 | S8: =$J$2 -> 0 | T8: =$K$2 -> 0.71858731 | V8: 0.65 | X8: 课程目标5 | Y8: ='3课程达成度分析报告'!T75 -> 0 | Z8: 0.65
A9: 6 | B9: ='1课程考核方式及成绩组成'!D16 -> 190301003 | C9: ='1课程考核方式及成绩组成'!E16 -> 何中尉 | D9: =OFFSET('4学生课程目标达成度'!J$5,(ROW(D9)-3)*7,) -> 0.88888889 | E9: =OFFSET('4学生课程目标达成度'!J$6,(ROW(E9)-3)*7,) -> 0.8 | F9: =OFFSET('4学生课程目标达成度'!J$7,(ROW(F9)-3)*7,) -> 0.58823529 | G9: =OFFSET('4学生课程目标达成度'!J$8,(ROW(G9)-3)*7,) -> 0.85 | H9: =OFFSET('4学生课程目标达成度'!J$9,(ROW(H9)-3)*7,) -> 0 | I9: =OFFSET('4学生课程目标达成度'!J$10,(ROW(I9)-3)*7,) -> 0 | J9: =OFFSET('4学生课程目标达成度'!J$11,(ROW(J9)-3)*7,) -> 0 | K9: =OFFSET('4学生课程目标达成度'!K$5,(ROW(K9)-3)*7,) -> 0.77539216 | M9: =$D$2 -> 0.82047872 | N9: =$E$2 -> 0.77990544 | O9: =$F$2 -> 0.5598665 | P9: =$G$2 -> 0.78801418 | Q9: =$H$2 -> 0 | R9: =$I$2 -> 0 | S9: =$J$2 -> 0 | T9: =$K$2 -> 0.71858731 | V9: 0.65 | X9: 课程目标6 | Y9: ='3课程达成度分析报告'!T81 -> 0 | Z9: 0.65
A10: 7 | B10: ='1课程考核方式及成绩组成'!D17 -> 190301004 | C10: ='1课程考核方式及成绩组成'!E17 -> 王华鹏 | D10: =OFFSET('4学生课程目标达成度'!J$5,(ROW(D10)-3)*7,) -> 0.25 | E10: =OFFSET('4学生课程目标达成度'!J$6,(ROW(E10)-3)*7,) -> 0.23333333 | F10: =OFFSET('4学生课程目标达成度'!J$7,(ROW(F10)-3)*7,) -> 0.23529412 | G10: =OFFSET('4学生课程目标达成度'!J$8,(ROW(G10)-3)*7,) -> 0 | H10: =OFFSET('4学生课程目标达成度'!J$9,(ROW(H10)-3)*7,) -> 0 | I10: =OFFSET('4学生课程目标达成度'!J$10,(ROW(I10)-3)*7,) -> 0 | J10: =OFFSET('4学生课程目标达成度'!J$11,(ROW(J10)-3)*7,) -> 0 | K10: =OFFSET('4学生课程目标达成度'!K$5,(ROW(K10)-3)*7,) -> 0.16632353 | M10: =$D$2 -> 0.82047872 | N10: =$E$2 -> 0.77990544 | O10: =$F$2 -> 0.5598665 | P10: =$G$2 -> 0.78801418 | Q10: =$H$2 -> 0 | R10: =$I$2 -> 0 | S10: =$J$2 -> 0 | T10: =$K$2 -> 0.71858731 | V10: 0.65 | X10: 课程目标7 | Y10: ='3课程达成度分析报告'!T87 -> 0 | Z10: 0.65
